Workbook
Name \0: #REF!
Name \d: #REF!
Name \l: #REF!
Name \r: #REF!
Name __FDS_USED_FOR_REUSING_RANGE_IDS_RECYCLE: {1,1,1,1,1,1,1,1,1,1,1,1,1,1,1,1,1,1,1,1,1,1,1,1,1,1,1,1,1,1}
Name _2_DC_Power_Transistors: #REF!
Name _2_Total_Power_Discrete: #REF!
Name _3_DC_Power_Diodes: #REF!
Name _3_Power_Transistors_Breakout: #REF!
Name _4_RF_Power_Discrete: #REF!
Name _4_Total_RF_Discrete: #REF!
Name _5_Small_Signal_Discrete: #REF!
Name _5_Total_Small_Signal_Discrete: #REF!
Name _6_End_Market_Overview: #REF!
Name _7_Glossary_of_Terms: #REF!
Name africaCountries: #REF!
Name Amort: #REF!
Name Arial: #REF!
Name asiaPacificExJapanCountries: #REF!
Name asiaPacificStates: #REF!
Name Asset_turns: #REF!
Name Assets: #REF!
Name b: #REF!
Name c_: #REF!
Name Case: #REF!
Name CaseCount: #REF!
Name CASH: #REF!
Name cd: #REF!
Name centralEasternEuropeCountries: #REF!
Name CF_OP_GR: "'=BackSheet!$D$239:$AG$239"
Name CF_PR_DV: "'=BackSheet!$D$241:$AG$241"
Name Choices_Wrapper: #REF!
Name CompanyList: #REF!
Name CompanyName: #REF!
Name CompanyPicked: #REF!
Name CompList11: #REF!
Name consumerDemandExposure: #REF!
Name consumersExposure: #REF!
Name CONT: #REF!
Name Conv_mark: 1
Name CurrentYear: #REF!
Name datalength: COUNTA(#REF!)
Name dataseries_minus_space_2: OFFSET(#REF!,0,0,COUNTIF(#REF!,">""")+1,1)
Name dataseries1: OFFSET(#REF!,0,0,COUNTA(#REF!),1)
Name DCYear: #REF!
Name Debt: #REF!
Name Debt_95: #REF!
Name Debt_96: #REF!
Name Debt_97: #REF!
Name Debt_Cap: #REF!
Name Def: #REF!
Name Definitions: #REF!
Name Dep: #REF!
Name developedEuropeExUKCountries: #REF!
Name DEVELOPMENT: 5
Name DevTotCon: #REF!
Name domesticAndForeignExposure: #REF!
Name domesticCostExposure: #REF!
Name DPYear: #REF!
Name Dropdown_lookup: #REF!

Sheet CircularReferenceAlert
B2: This workbook contains formulas which intentionally use circular reference calculation. These calculations can be resolved as intended by the originating analyst by applying the following settings in the File >> Options >> Formulas:
B5: 1) Select the Enable iterative calculation check box
B6: 2) Set Maximum Iterations = 100
B7: 3) Set Maximum Change = 0.001
B9: Failure to apply these settings can result in incorrect calculation or unexpected termination of your Microsoft Excel session.

Sheet ImportantDisclosures
A2: 20 Bank Street, Canary Wharf
A3: London E14 4AD
A4: United Kingdom
A5: Tel: +44 (0)20 7425 8000
A7: Authors: Lee Simpson,Terence Tsui,Nigel van Putten,Amelia Scicluna
A8: Date: 16 Apr 2026
A10: Ticker: ASML.AS
A11: Stock Rating: Overweight
A12: Industry: Technology - European Semiconductors
A13: Industry View: In-Line
A14: Price as of 16 Apr 2026: 1230.00
A15: Target Price: 1400.00
... A123: Equal-weight and Not-Rated to hold and Underweight to sell recommendations, respectively.
B125: Coverage Universe | D125: Investment Banking Clients (IBC) | G125: Other Material Investment Services Clients (MISC)
A126: Stock Rating Category | B126: Count | C126: % of Total | D126: Count | E126: % of Total IBC | F126: % of Rating Category | G126: Count | H126: % of Total Other MISC
A127: Overweight/Buy | B127: 1534 | C127: 0.42 | D127: 461 | E127: 0.5 | F127: 0.3 | G127: 698 | H127: 0.43
A128: Equal-weight/Hold | B128: 1573 | C128: 0.43 | D128: 372 | E128: 0.4 | F128: 0.24 | G128: 716 | H128: 0.44
A129: Not-Rated/Hold | B129: 4 | C129: 0 | D129: 1 | E129: 0 | F129: 0.25 | G129: 1 | H129: 0
A130: Underweight/Sell | B130: 568 | C130: 0.15 | D130: 89 | E130: 0.1 | F130: 0.16 | G130: 209 | H130: 0.13
A131: Total | B131: 3679 | D131: 923 | G131: 1624
A133: Data include common stock and ADRs currently assigned ratings. Investment Banking Clients are companies
A134: from whom Morgan Stanley received investment banking compensation in the last 12 months. Due to rounding
A135: off of decimals, the percentages provided in the "% of total" column may not add up to exactly 100
A136: percent.
A138: Analyst Stock Ratings
A140: Overweight (O). The stock's total return is expected to exceed the average total return of the analyst's
A141: industry (or industry team's) coverage universe, on a risk-adjusted basis, over the next 12-18 months.
A143: Equal-weight (E). The stock's total return is expected to be in line with the average total return of
A144: the analyst's industry (or industry team's) coverage universe, on a risk-adjusted basis, over the next
A145: 12-18 months.
A147: Not-Rated (NR). Currently the analyst does not have adequate conviction about the stock's total return
A148: relative to the average total return of the analyst's industry (or industry team's) coverage universe,
... A424: © Copyright 2026 Morgan Stanley

Sheet Cover
C3: Morgan Stanley Equity Research Europe
C4: European Technology | I4: Analyst | J4: Lee Simpson
C5: Sector | E5: Semiconductors | I5: Email | J5: lee.simpson@morganstanley.com
C6: Last updated | E6: =TODAY() -> 46128 | I6: Tel. | J6: +44 (0)20 7425 3378
C11: Company Details | I11: Company Description: Dutch-based (Veldhoven) ASML Holdings NV is the dominant supplier (75% share) of lithography equipment to the global semiconductor industry. ASML designs, develops, integrates, markets and services lithography systems, which are essential for the fabrication of semiconductor chips. The company retains a focus on next-gen R&D and marketing whilst outsourcing c.85% of its production to third-party system assemblers. Tools based on immersion technology form the rump of ASML’s order book which includes next generation, Extreme Ultraviolet (EUV) toolsets. Formerly part of Philips, ASML was spun off in 1984 (renamed 'Philips Labs'), with the parent keeping a 50% stake and ASM International acquiring the other half. By 1988, ASMI pulled out of the venture and Philips Labs was renamed as ASML and floated on the Amsterdam and New York exchanges. Today, ASML has a c. 80% free float.
C12: Name | E12: ASML Holdings NV
C13: Ticker | E13: ASML.AS
C14: Fiscal Year End | E14: 44926
C15: Accounting GAAP | E15: US GAAP
C16: Currency - Report | E16: EUR
C17: Currency - Quote | E17: EUR
C23: Equity Details | I23: Contact Details
C24: Company Name | E24: =$E$12 -> ASML Holdings NV | I24: Website | K24: www.asml.com | N24: Address | O24: ASML Netherlands B.V.
C25: Main Ticker | E25: =E13 -> ASML.AS | I25: Founded | K25: 1984 | O25: De Run 6501
C26: Share Price | E26: {=_xll.FDS("ASML-NL","P_PRICE(0)")} -> 1263.4 | I26: Country of Incorp. | K26: Netherlands | O26: 5504 DR Veldhoven
I27: Listed Exchange | K27: Amsterdam (Listed AEX) | O27: The Netherlands
N28: Tel. | O28: +31 40 268 3000
I30: Management Details
I31: CEO | K31: Peter Wennink
I32: CFO | K32: Roger Dassen
I33: Investor Relations | K33: Skip Miller (Global), Pete Convertito (US), Peter Cheang (Asia)
C38: Sources for data in this workbook include:
C39: Morgan Stanley estimates
C40: Company reports

Sheet Sales
A1: =Cover!$E$12 -> ASML Holdings NV | EG1: =EG10 -> 8766.5 | EH1: =EH10 -> 8339.4 | EI1: =EI10 -> 10142.5 | EJ1: =EJ10 -> 10425.195 | EK1: =EK10 -> 37673.595 | EL1: =EL10 -> 48011.948
A2: Sales, Units, Bookings & Backlog | ER2: i | ES2: o | ET2: u | EU2: aa | EV2: ag | EW2: am | EX2: as | EY2: ay | EZ2: be | FA2: bk | FB2: bq | FC2: bw | FD2: cc | FE2: ci | FF2: co | FG2: cu | FH2: da | FI2: dg | FJ2: dm | FK2: ds | FL2: dy | FM2: ee | FN2: ek | FO2: el
A3: EURm unless otherwise stated | E3: 1Q04 | F3: 2Q04 | G3: 3Q04 | H3: 4Q04 | I3: 2004 | K3: 1Q05 | L3: 2Q05 | M3: 3Q05 | N3: 4Q05 | O3: 2005 | Q3: 1Q06 | R3: 2Q06 | S3: 3Q06 | T3: 4Q06 | U3: 2006 | W3: 1Q07 | X3: 2Q07 | Y3: 3Q07 | Z3: 4Q07 | AA3: 2007 | AC3: 1Q08 | AD3: 2Q08 | AE3: 3Q08 | AF3: 4Q08 | AG3: 2008 | AI3: 1Q09 | AJ3: 2Q09 | AK3: 3Q09 | AL3: 4Q09 | AM3: 2009 | AO3: 1Q10 | AP3: 2Q10 | AQ3: 3Q10 | AR3: 4Q10 | AS3: 2010 | AU3: 1Q11 | AV3: 2Q11 | AW3: 3Q11 | AX3: 4Q11 | AY3: 2011 | BA3: 1Q12 | BB3: 2Q12 | BC3: 3Q12 | BD3: 4Q12 | BE3: 2012 | BG3: 1Q13 | BH3: 2Q13 | BI3: 3Q13 | BJ3: 4Q13 | BK3: 2013 | BM3: 1Q14 | BN3: 2Q14 | BO3: 3Q14 | BP3: 4Q14 | BQ3: 2014 | BS3: 1Q15 | BT3: 2Q15 | BU3: 3Q15 | BV3: 4Q15 | BW3: 2015 | BY3: 1Q16 | BZ3: 2Q16 | CA3: 3Q16 | CB3: 4Q16 | CC3: 2016 | CE3: 1Q17 | CF3: 2Q17 | CG3: 3Q17 | CH3: 4Q17 | CI3: 2017 | CK3: 1Q18 | CL3: 2Q18 | CM3: 3Q18 | CN3: 4Q18 | CO3: 2018 | CQ3: 1Q19 | CR3: 2Q19 | CS3: 3Q19 | CT3: 4Q19 | CU3: 2019 | CW3: 1Q20 | CX3: 2Q20 | CY3: 3Q20 | CZ3: 4Q20 | DA3: 2020 | DC3: 1Q21 | DD3: 2Q21 | DE3: 3Q21 | DF3: 4Q21 | DG3: 2021 | DI3: 1Q22 | DJ3: 2Q22 | DK3: 3Q22 | DL3: 4Q22 | DM3: 2022 | DO3: 1Q23 | DP3: 2Q23 | DQ3: 3Q23 | DR3: 4Q23 | DS3: 2023 | DU3: 1Q24 | DV3: 2Q24 | DW3: 3Q24 | DX3: 4Q24 | DY3: 2024 | EA3: 1Q25 | EB3: 2Q25 | EC3: 3Q25 | ED3: 4Q25 | EE3: 2025 | EG3: 1Q26 | EH3: 2Q26e | EI3: 3Q26e | EJ3: 4Q26e | EK3: 2026e | EL3: 2027e | EN3: Notes | ER3: 2004 | ES3: 2005 | ET3: 2006 | EU3: 2007 | EV3: 2008 | EW3: 2009 | EX3: 2010 | EY3: 2011 | EZ3: 2012 | FA3: 2013 | FB3: 2014 | FC3: 2015 | FD3: 2016 | FE3: 2017 | FF3: 2018 | FG3: 2019 | FH3: 2020 | FI3: 2021 | FJ3: 2022 | FK3: 2023 | FL3: 2024 | FM3: 2025e | FN3: 2026e | FO3: 2027e | FP3: 2028e | FQ3: 2029e | FR3: 2030e
A6: REVENUE SUMMARY | ER6: =ER$3 -> 2004 | ES6: =ES$3 -> 2005 | ET6: =ET$3 -> 2006 | EU6: =EU$3 -> 2007 | EV6: =EV$3 -> 2008 | EW6: =EW$3 -> 2009 | EX6: =EX$3 -> 2010 | EY6: =EY$3 -> 2011 | ... FD6: =FD$3 -> 2016
B8: Net System Sales | H8: 709.839 | I8: 2174.908 | K8: 632.135 | L8: 680.534 | M8: 458.992 | N8: =O8-M8-L8-K8 -> 456.017 | O8: 2227.678 | Q8: 553.101 | R8: 840.817 | S8: 856.556 | T8: =U8-S8-R8-Q8 -> 978.591 | U8: 3229.065 | W8: 858.948 | X8: 825.817 | Y8: 843.232 | Z8: 852.824 | AA8: 3380.821 | AC8: 819.986 | AD8: 725.586 | AE8: 590.723 | AF8: 380.466 | AG8: =AC8+AD8+AE8+AF8 -> 2516.761 | AI8: 101.1 | AJ8: 183.259 | AK8: 458.691 | AL8: 431.808 | AM8: =AI8+AJ8+AK8+AL8 -> 1174.858 | AO8: 631.6 | AP8: 923 | AQ8: 1027 | AR8: 1313.1 | AS8: =AO8+AP8+AQ8+AR8 -> 3894.7 | AU8: 1284.4 | AV8: 1333.6 | AW8: 1273.2 | AX8: 992.7 | AY8: =AU8+AV8+AW8+AX8 -> 4883.9 | BA8: 1050 | BB8: 984.8 | BC8: 1000.3 | BD8: 766.5 | BE8: =BA8+BB8+BC8+BD8 -> 3801.6 | BG8: 676.9 | BH8: 915.5 | BI8: 959.5 | BJ8: 1441.2 | BK8: =BG8+BH8+BI8+BJ8 -> 3993.1 | BM8: 1030 | BN8: 1243 | BO8: 884.5 | BP8: 1085.3 | BQ8: =BM8+BN8+BO8+BP8 -> 4242.8 | BS8: 1246.5 | BT8: 1134.5 | BU8: 975.3 | BV8: 880.9 | BW8: =BS8+BT8+BU8+BV8 -> 4237.2 | BY8: 859.8 | BZ8: 1265.4 | CA8: 1257.7 | CB8: 1289.1 | CC8: =BY8+BZ8+CA8+CB8 -> 4672 | CE8: 1215.8 | CF8: 1384.1 | CG8: 1818.9 | CH8: 1954.9 | CI8: =CE8+CF8+CG8+CH8 -> 6373.7 | CK8: 1667.7 | CL8: 2086.5 | CM8: 2080.6 | CN8: 2424.3 | CO8: =CK8+CL8+CM8+CN8 -> 8259.1 | CQ8: 1689 | CR8: 1850.8 | CS8: 2325.6 | CT8: 3130.7 | CU8: =CQ8+CR8+CS8+CT8 -> 8996.1 | CW8: 1584 | CX8: 2438.6 | CY8: 3095.6 | CZ8: 3198.3 | DA8: =CW8+CX8+CY8+CZ8 -> 10316.5 | DC8: 3128.8 | DD8: 2949.6 | DE8: 4111.1 | DF8: 3463.2 | DG8: =DC8+DD8+DE8+DF8 -> 13652.7 | DI8: 2287.2 | DJ8: 4140.5 | DK8: 4254.7 | DL8: 4747.9 | DM8: =SUM(DI8:DL8) -> 15430.3 | DO8: 5341.8 | DP8: 5606.1 | DQ8: 5308.2 | DR8: 5682.5 | DS8: =SUM(DO8:DR8) -> 21938.6 | DU8: 3965.9 | DV8: 4760.9 | DW8: 5926 | DX8: 7115.9 | DY8: =DU8+DV8+DW8+DX8 -> 21768.7 | EA8: 5740.4 | EB8: 5596.1 | EC8: 5553.8 | ED8: 7584 | EE8: =EA8+EB8+EC8+ED8 -> 24474.3 | EG8: 6279 | EH8: 5870 | EI8: 7930 | EJ8: 8297.995 | EK8: =EG8+EH8+EI8+EJ8 -> 28376.995 | EL8: =EL55 -> 37458.148 | ER8: =I8 -> 2174.908 | ES8: =O8 -> 2227.678 | ET8: =U8 -> 3229.065 | EU8: =AA8 -> 3380.821 | EV8: =AG8 -> 2516.761 | EW8: =AM8 -> 1174.858 | EX8: =AS8 -> 3894.7 | EY8: =AY8 -> 4883.9 | EZ8: =BE8 -> 3801.6 | FA8: =BK8 -> 3993.1 | FB8: =BQ8 -> 4242.8 | FC8: =BW8 -> 4237.2 | FD8: =CC8 -> 4672 | FE8: =CI8 -> 6373.7 | FF8: =CO8 -> 8259.1 | FG8: =CU8 -> 8996.1 | FH8: =DA8 -> 10316.5 | FI8: =DG8 -> 13652.7 | FJ8: =DM8 -> 15430.3 | FK8: =DS8 -> 21938.6 | FL8: =DY8 -> 21768.7 | FM8: =EE8 -> 24474.3 | FN8: =EK8 -> 28376.995 | FO8: =EL8 -> 37458.148 | FP8: =FP55 -> 30338.833 | FQ8: =FQ55 -> 21030 | FR8: =FR55 -> 25940
B9: Net Service & Field Option sales | H9: 75.323 | I9: 290.469 | K9: 52.545 | L9: 82.731 | M9: 74.161 | N9: =O9-M9-L9-K9 -> 91.852 | O9: 301.289 | Q9: 76.289 | R9: 100.937 | S9: 101.877 | T9: =U9-S9-R9-Q9 -> 88.936 | U9: 368.039 | W9: 101.295 | X9: 104.405 | Y9: 91.142 | Z9: 120.063 | AA9: 416.905 | AC9: 99.222 | AD9: 118.571 | AE9: 105.77 | AF9: 113.354 | AG9: =AC9+AD9+AE9+AF9 -> 436.917 | AI9: 82.525 | AJ9: 93.341 | AK9: 96.581 | AL9: 148.758 | AM9: =AI9+AJ9+AK9+AL9 -> 421.205 | AO9: 110.2 | AP9: 145.7 | AQ9: 149 | AR9: 208.3 | AS9: =AO9+AP9+AQ9+AR9 -> 613.2 | AU9: 167.8 | AV9: 195.8 | AW9: 185.3 | AX9: 218.2 | AY9: =AU9+AV9+AW9+AX9 -> 767.1 | BA9: 201.9 | BB9: 242.9 | BC9: 228.5 | BD9: 256.6 | BE9: =BA9+BB9+BC9+BD9 -> 929.9 | BG9: 215.2 | BH9: 271.2 | BI9: 358.7 | BJ9: 407.1 | BK9: =BG9+BH9+BI9+BJ9 -> 1252.2 | BM9: 366.5 | BN9: 400.6 | BO9: 437.7 | BP9: 408.7 | BQ9: =BM9+BN9+BO9+BP9 -> 1613.5 | BS9: 403.4 | BT9: 519.6 | BU9: 573.9 | BV9: 553.3 | BW9: =BS9+BT9+BU9+BV9 -> 2050.2 | BY9: 473.4 | BZ9: 474.2 | CA9: 556.9 | CB9: 618.3 | CC9: =BY9+BZ9+CA9+CB9 -> 2122.8 | CE9: 727.8 | CF9: 717.3 | CG9: 628.5 | CH9: 605.5 | CI9: =CE9+CF9+CG9+CH9 -> 2679.1 | CK9: 617.3 | CL9: 653.9 | CM9: 695.5 | CN9: 718.2 | CO9: =CK9+CL9+CM9+CN9 -> 2684.9 | CQ9: 540.1 | CR9: 717.1 | CS9: 660.9 | CT9: 905.7 | CU9: =CQ9+CR9+CS9+CT9 -> 2823.8 | CW9: 856.6 | CX9: 887.1 | CY9: 862.4 | CZ9: 1055.8 | DA9: =CW9+CX9+CY9+CZ9 -> 3661.9 | DC9: 1235.1 | DD9: 1070.6 | DE9: 1130.2 | DF9: 1522.4 | DG9: =DC9+DD9+DE9+DF9 -> 4958.3 | DI9: 1247.2 | DJ9: 1290 | DK9: 1523.6 | DL9: 1682.3 | DM9: =DI9+DJ9+DK9+DL9 -> 5743.1 | DO9: 1404.4 | DP9: 1296.2 | DQ9: 1364.8 | DR9: 1554.5 | DS9: =DO9+DP9+DQ9+DR9 -> 5619.9 | DU9: 1324.1 | DV9: 1481.9 | DW9: 1541.3 | DX9: 2146.9 | DY9: =DU9+DV9+DW9+DX9 -> 6494.2 | EA9: 2001.1 | EB9: 2095.6 | EC9: 1962.2 | ED9: 2134 | EE9: =EA9+EB9+EC9+ED9 -> 8192.9 | EG9: 2487.5 | EH9: 2469.4 | EI9: 2212.5 | EJ9: 2127.2 | EK9: =EG9+EH9+EI9+EJ9 -> 9296.6 | EL9: =EL37 -> 10553.8 | ER9: =I9 -> 290.469 | ES9: =O9 -> 301.289 | ET9: =U9 -> 368.039 | EU9: =AA9 -> 416.905 | EV9: =AG9 -> 436.917 | EW9: =AM9 -> 421.205 | EX9: =AS9 -> 613.2 | EY9: =AY9 -> 767.1 | EZ9: =BE9 -> 929.9 | FA9: =BK9 -> 1252.2 | FB9: =BQ9 -> 1613.5 | FC9: =BW9 -> 2050.2 | FD9: =CC9 -> 2122.8 | FE9: =CI9 -> 2679.1 | FF9: =CO9 -> 2684.9 | FG9: =CU9 -> 2823.8 | FH9: =DA9 -> 3661.9 | FI9: =DG9 -> 4958.3 | FJ9: =DM9 -> 5743.1 | FK9: =DS9 -> 5619.9 | FL9: =DY9 -> 6494.2 | FM9: =EE9 -> 8192.9 | FN9: =EK9 -> 9296.6 | FO9: =EL9 -> 10553.8 | FP9: =FP37 -> 10957.588 | FQ9: =FQ37 -> 1107.5 | FR9: =FR37 -> 0
B10: Net Sales | E10: 453.485 | F10: 616.258 | G10: 610.472 | H10: =H8+H9 -> 785.162 | I10: =I8+I9 -> 2465.377 | K10: =K8+K9 -> 684.68 | L10: =L8+L9 -> 763.265 | M10: =M8+M9 -> 533.153 | N10: =N8+N9 -> 547.869 | O10: =O8+O9 -> 2528.967 | Q10: =Q8+Q9 -> 629.39 | R10: =R8+R9 -> 941.754 | S10: =S8+S9 -> 958.433 | T10: =T8+T9 -> 1067.527 | U10: =U8+U9 -> 3597.104 | W10: =W8+W9 -> 960.243 | X10: =X8+X9 -> 930.222 | Y10: =Y8+Y9 -> 934.374 | Z10: =Z8+Z9 -> 972.887 | AA10: =AA8+AA9 -> 3797.726 | AC10: =AC8+AC9 -> 919.208 | AD10: =AD8+AD9 -> 844.157 | AE10: =AE8+AE9 -> 696.493 | AF10: =AF8+AF9 -> 493.82 | AG10: =AG8+AG9 -> 2953.678 | AI10: =AI8+AI9 -> 183.625 | AJ10: =AJ8+AJ9 -> 276.6 | AK10: =AK8+AK9 -> 555.272 | AL10: =AL8+AL9 -> 580.566 | AM10: =AM8+AM9 -> 1596.063 | AO10: =AO8+AO9 -> 741.8 | AP10: =AP8+AP9 -> 1068.7 | AQ10: =AQ8+AQ9 -> 1176 | AR10: =AR8+AR9 -> 1521.4 | AS10: =AS8+AS9 -> 4507.9 | AU10: =AU8+AU9 -> 1452.2 | AV10: =AV8+AV9 -> 1529.4 | AW10: =AW8+AW9 -> 1458.5 | AX10: =AX8+AX9 -> 1210.9 | AY10: =AY8+AY9 -> 5651 | BA10: =BA8+BA9 -> 1251.9 | BB10: =BB8+BB9 -> 1227.7 | BC10: =BC8+BC9 -> 1228.8 | BD10: =BD8+BD9 -> 1023.1 | BE10: =BE8+BE9 -> 4731.5 | BG10: =BG8+BG9 -> 892.1 | BH10: =BH8+BH9+BH11 -> 1218.7 | BI10: =BI8+BI9+BI11 -> 1392.2 | BJ10: =BJ8+BJ9+BJ11 -> 1922.3 | BK10: =BK8+BK9+BK11 -> 5425.3 | BM10: =BM8+BM9+BM11 -> 1396.5 | BN10: =BN8+BN9+BN11 -> 1643.6 | BO10: =BO8+BO9+BO11 -> 1322.2 | BP10: =BP8+BP9+BP11 -> 1494 | BQ10: =BQ8+BQ9+BQ11 -> 5856.3 | BS10: =BS8+BS9+BS11 -> 1649.9 | BT10: =BT8+BT9+BT11 -> 1654.1 | BU10: =BU8+BU9+BU11 -> 1549.2 | BV10: =BV8+BV9+BV11 -> 1434.2 | BW10: =BW8+BW9+BW11 -> 6287.4 | BY10: =BY8+BY9 -> 1333.2 | BZ10: =BZ8+BZ9 -> 1739.6 | CA10: =CA8+CA9 -> 1814.6 | CB10: =CB8+CB9 -> 1907.4 | CC10: =CC8+CC9 -> 6794.8 | CE10: =CE8+CE9 -> 1943.6 | CF10: =CF8+CF9 -> 2101.4 | CG10: =CG8+CG9 -> 2447.4 | CH10: =CH8+CH9 -> 2560.4 | CI10: =CI8+CI9 -> 9052.8 | CK10: =CK8+CK9 -> 2285 | CL10: =CL8+CL9 -> 2740.4 | CM10: =CM8+CM9 -> 2776.1 | CN10: =CN8+CN9 -> 3142.5 | CO10: =CO8+CO9 -> 10944 | CQ10: =CQ8+CQ9 -> 2229.1 | CR10: =CR8+CR9 -> 2567.9 | CS10: =CS8+CS9 -> 2986.5 | CT10: =CT8+CT9 -> 4036.4 | CU10: =CU8+CU9 -> 11819.9 | CW10: =CW8+CW9 -> 2440.6 | CX10: =CX8+CX9 -> 3325.7 | CY10: =CY8+CY9 -> 3958 | CZ10: =CZ8+CZ9 -> 4254.1 | DA10: =DA8+DA9 -> 13978.4 | DC10: =DC8+DC9 -> 4363.9 | DD10: =DD8+DD9 -> 4020.2 | DE10: =DE8+DE9 -> 5241.3 | DF10: =DF8+DF9 -> 4985.6 | DG10: =DG8+DG9 -> 18611 | DI10: =DI8+DI9 -> 3534.4 | DJ10: =DJ8+DJ9 -> 5430.5 | DK10: =DK8+DK9 -> 5778.3 | DL10: =DL8+DL9 -> 6430.2 | DM10: =DM8+DM9 -> 21173.4 | DO10: =SUM(DO8:DO9) -> 6746.2 | DP10: =SUM(DP8:DP9) -> 6902.3 | DQ10: =SUM(DQ8:DQ9) -> 6673 | DR10: =SUM(DR8:DR9) -> 7237 | DS10: =DS8+DS9 -> 27558.5 | DU10: =DU8+DU9 -> 5290 | DV10: =DV8+DV9 -> 6242.8 | DW10: =DW8+DW9 -> 7467.3 | DX10: =DX8+DX9 -> 9262.8 | DY10: =DY8+DY9 -> 28262.9 | EA10: =EA8+EA9 -> 7741.5 | EB10: =EB8+EB9 -> 7691.7 | EC10: =EC8+EC9 -> 7516 | ED10: =ED8+ED9 -> 9718 | EE10: =EE8+EE9 -> 32667.2 | EG10: =EG8+EG9 -> 8766.5 | EH10: =EH8+EH9 -> 8339.4 | EI10: =EI8+EI9 -> 10142.5 | EJ10: =EJ8+EJ9 -> 10425.195 | EK10: =EK8+EK9 -> 37673.595 | EL10: =SUM(EL9,EL8) -> 48011.948 | ER10: =SUM(ER9,ER8) -> 2465.377 | ES10: =SUM(ES9,ES8) -> 2528.967 | ET10: =SUM(ET9,ET8) -> 3597.104 | EU10: =SUM(EU9,EU8) -> 3797.726 | EV10: =SUM(EV9,EV8) -> 2953.678 | EW10: =SUM(EW9,EW8) -> 1596.063 | EX10: =SUM(EX9,EX8) -> 4507.9 | EY10: =SUM(EY9,EY8) -> 5651 | ... FR10: =SUM(FR9,FR8) -> 25940
BH11: 32 | BI11: 74 | BJ11: =($BK$11-$BH$11)/2 -> 74 | BK11: 180
B12: Growth q/q
B13: System sales | K13: =K8/H8-1 -> -0.10946708 | L13: =L8/K8-1 -> 0.076564341 | M13: =M8/L8-1 -> -0.32554141 | N13: =N8/M8-1 -> -0.0064815945 | Q13: =Q8/N8-1 -> 0.21289557 | R13: =R8/Q8-1 -> 0.52018709 | S13: =S8/R8-1 -> 0.018718699 | T13: =T8/S8-1 -> 0.14247171 | W13: =W8/T8-1 -> -0.12226047 | X13: =X8/W8-1 -> -0.038571602 | Y13: =Y8/X8-1 -> 0.021088207 | Z13: =Z8/Y8-1 -> 0.01137528 | AC13: =AC8/Z8-1 -> -0.038505014 | AD13: =AD8/AC8-1 -> -0.11512392 | AE13: =AE8/AD8-1 -> -0.1858677 | AF13: =AF8/AE8-1 -> -0.35593163 | AI13: =AI8/AF8-1 -> -0.73427323 | AJ13: =AJ8/AI8-1 -> 0.81265084 | AK13: =AK8/AJ8-1 -> 1.5029657 | AL13: =AL8/AK8-1 -> -0.058608083 | AO13: =AO8/AL8-1 -> 0.46268712 | AP13: =AP8/AO8-1 -> 0.46136795 | AQ13: =AQ8/AP8-1 -> 0.11267606 | AR13: =AR8/AQ8-1 -> 0.27857838 | AU13: =AU8/AR8-1 -> -0.021856675 | AV13: =AV8/AU8-1 -> 0.038305824 | AW13: =AW8/AV8-1 -> -0.045290942 | AX13: =AX8/AW8-1 -> -0.22031103 | BA13: =BA8/AX8-1 -> 0.057721366 | BB13: =BB8/BA8-1 -> -0.062095238 | BC13: =BC8/BB8-1 -> 0.015739236 | BD13: =BD8/BC8-1 -> -0.23372988 | BG13: =BG8/BD8-1 -> -0.11689498 | BH13: =BH8/BG8-1 -> 0.35248929 | BI13: =BI8/BH8-1 -> 0.048061169 | BJ13: =BJ8/BI8-1 -> 0.50203231 | BM13: =BM8/BJ8-1 -> -0.28531779 | BN13: =BN8/BM8-1 -> 0.20679612 | BO13: =BO8/BN8-1 -> -0.28841512 | BP13: =BP8/BO8-1 -> 0.22702092 | BS13: =BS8/BP8-1 -> 0.14853036 | BT13: =BT8/BS8-1 -> -0.089851584 | BU13: =BU8/BT8-1 -> -0.14032613 | BV13: =BV8/BU8-1 -> -0.096790731 | BY13: =BY8/BV8-1 -> -0.023952776 | BZ13: =BZ8/BY8-1 -> 0.47173761 | CA13: =CA8/BZ8-1 -> -0.0060850324 | CB13: =CB8/CA8-1 -> 0.024966208 | CE13: =CE8/CB8-1 -> -0.056861376 | CF13: =CF8/CE8-1 -> 0.13842737 | CG13: =CG8/CF8-1 -> 0.31413915 | CH13: =CH8/CG8-1 -> 0.074770466 | CK13: =CK8/CH8-1 -> -0.14691289 | CL13: =CL8/CK8-1 -> 0.2511243 | CM13: =CM8/CL8-1 -> -0.0028277019 | CN13: =CN8/CM8-1 -> 0.16519273 | CQ13: =CQ8/CN8-1 -> -0.30330405 | CR13: =CR8/CQ8-1 -> 0.095796329 | CS13: =CS8/CR8-1 -> 0.25653771 | CT13: =CT8/CS8-1 -> 0.34619023 | CW13: =CW8/CT8-1 -> -0.49404287 | CX13: =CX8/CW8-1 -> 0.5395202 | CY13: =CY8/CX8-1 -> 0.26941688 | CZ13: =CZ8/CY8-1 -> 0.033176121 | DC13: =DC8/CZ8-1 -> -0.021730294 | DD13: =DD8/DC8-1 -> -0.057274354 | DE13: =DE8/DD8-1 -> 0.39378221 | DF13: =DF8/DE8-1 -> -0.15759772 | DI13: =DI8/DF8-1 -> -0.33957034 | DJ13: =DJ8/DI8-1 -> 0.81029206 | DK13: =DK8/DJ8-1 -> 0.02758121 | DL13: =DL8/DK8-1 -> 0.11591887 | DO13: =DO8/DL8-1 -> 0.12508688 | DP13: =DP8/DO8-1 -> 0.049477704 | DQ13: =DQ8/DP8-1 -> -0.053138546 | DR13: =DR8/DQ8-1 -> 0.070513545 | DU13: =DU8/DR8-1 -> -0.30208535 | DV13: =DV8/DS8-1 -> -0.7829898 | DW13: =DW8/DV8-1 -> 0.24472264 | DX13: =DX8/DW8-1 -> 0.20079312 | EA13: =EA8/DX8-1 -> -0.19329951 | EB13: =EB8/DY8-1 -> -0.74292907 | EC13: =EC8/EB8-1 -> -0.0075588356 | ED13: =ED8/EC8-1 -> 0.36555151 | EG13: =EG8/ED8-1 -> -0.17207278 | EH13: =EH8/EG8-1 -> -0.065137761 | EI13: =EI8/EH8-1 -> 0.35093697 | EJ13: =EJ8/EI8-1 -> 0.046405422
B14: Field option and service sales | K14: =K9/H9-1 -> -0.30240431 | L14: =L9/K9-1 -> 0.57447902 | M14: =M9/L9-1 -> -0.10358874 | N14: =N9/M9-1 -> 0.23854856 | Q14: =Q9/N9-1 -> -0.16943561 | R14: =R9/Q9-1 -> 0.32308721 | S14: =S9/R9-1 -> 0.0093127396 | T14: =T9/S9-1 -> -0.12702573 | W14: =W9/T9-1 -> 0.1389651 | X14: =X9/W9-1 -> 0.030702404 | Y14: =Y9/X9-1 -> -0.12703415 | Z14: =Z9/Y9-1 -> 0.31731803 | AC14: =AC9/Z9-1 -> -0.17358387 | AD14: =AD9/AC9-1 -> 0.19500716 | AE14: =AE9/AD9-1 -> -0.10796063 | AF14: =AF9/AE9-1 -> 0.071702751 | AI14: =AI9/AF9-1 -> -0.27197099 | AJ14: =AJ9/AI9-1 -> 0.13106331 | AK14: =AK9/AJ9-1 -> 0.034711434 | AL14: =AL9/AK9-1 -> 0.54024083 | AO14: =AO9/AL9-1 -> -0.25919951 | AP14: =AP9/AO9-1 -> 0.32214156 | AQ14: =AQ9/AP9-1 -> 0.022649279 | AR14: =AR9/AQ9-1 -> 0.39798658 | AU14: =AU9/AR9-1 -> -0.19443111 | AV14: =AV9/AU9-1 -> 0.16686532 | AW14: =AW9/AV9-1 -> -0.053626149 | AX14: =AX9/AW9-1 -> 0.17754992 | BA14: =BA9/AX9-1 -> -0.074702108 | BB14: =BB9/BA9-1 -> 0.20307083 | BC14: =BC9/BB9-1 -> -0.059283656 | BD14: =BD9/BC9-1 -> 0.12297593 | BG14: =BG9/BD9-1 -> -0.16134061 | BH14: =BH9/BG9-1 -> 0.26022305 | BI14: =BI9/BH9-1 -> 0.32264012 | BJ14: =BJ9/BI9-1 -> 0.1349317 | BM14: =BM9/BJ9-1 -> -0.099729796 | BN14: =BN9/BM9-1 -> 0.093042292 | BO14: =BO9/BN9-1 -> 0.092611083 | BP14: =BP9/BO9-1 -> -0.066255426 | BS14: =BS9/BP9-1 -> -0.012967947 | BT14: =BT9/BS9-1 -> 0.28805156 | BU14: =BU9/BT9-1 -> 0.10450346 | BV14: =BV9/BU9-1 -> -0.035894755 | BY14: =BY9/BV9-1 -> -0.14440629 | BZ14: =BZ9/BY9-1 -> 0.0016899028 | CA14: =CA9/BZ9-1 -> 0.17439899 | CB14: =CB9/CA9-1 -> 0.11025319 | CE14: =CE9/CB9-1 -> 0.1770985 | CF14: =CF9/CE9-1 -> -0.01442704 | CG14: =CG9/CF9-1 -> -0.12379757 | CH14: =CH9/CG9-1 -> -0.036595068 | CK14: =CK9/CH9-1 -> 0.019488026 | CL14: =CL9/CK9-1 -> 0.059290458 | CM14: =CM9/CL9-1 -> 0.06361829 | CN14: =CN9/CM9-1 -> 0.03263839 | CQ14: =CQ9/CN9-1 -> -0.24798106 | CR14: =CR9/CQ9-1 -> 0.32771709 | CS14: =CS9/CR9-1 -> -0.078371217 | CT14: =CT9/CS9-1 -> 0.37040399 | CW14: =CW9/CT9-1 -> -0.054212212 | CX14: =CX9/CW9-1 -> 0.035605884 | CY14: =CY9/CX9-1 -> -0.027843535 | CZ14: =CZ9/CY9-1 -> 0.22425788 | DC14: =DC9/CZ9-1 -> 0.16982383 | DD14: =DD9/DC9-1 -> -0.1331876 | DE14: =DE9/DD9-1 -> 0.055669718 | DF14: =DF9/DE9-1 -> 0.34701823 | DI14: =DI9/DF9-1 -> -0.18076721 | DJ14: =DJ9/DI9-1 -> 0.03431687 | DK14: =DK9/DJ9-1 -> 0.18108527 | DL14: =DL9/DK9-1 -> 0.1041612 | DO14: =DO9/DL9-1 -> -0.16519051 | DP14: =DP9/DO9-1 -> -0.077043577 | DQ14: =DQ9/DP9-1 -> 0.052923931 | DR14: =DR9/DQ9-1 -> 0.13899472 | DU14: =DU9/DR9-1 -> -0.14821486 | DV14: =DV9/DS9-1 -> -0.73631203 | DW14: =DW9/DV9-1 -> 0.040083676 | DX14: =DX9/DW9-1 -> 0.39291507 | EA14: =EA9/DX9-1 -> -0.067911873 | EB14: =EB9/DY9-1 -> -0.67731206 | EC14: =EC9/EB9-1 -> -0.063657186 | ED14: =ED9/EC9-1 -> 0.087554785 | EG14: =EG9/ED9-1 -> 0.16565136 | EH14: =EH9/EG9-1 -> -0.0072763819 | EI14: =EI9/EH9-1 -> -0.10403337 | EJ14: =EJ9/EI9-1 -> -0.038553672
B15: Total q/q | K15: =K10/H10-1 -> -0.12797614 | L15: =L10/K10-1 -> 0.11477625 | M15: =M10/L10-1 -> -0.30148376 | N15: =N10/M10-1 -> 0.027601833 | Q15: =Q10/N10-1 -> 0.14879652 | R15: =R10/Q10-1 -> 0.49629641 | S15: =S10/R10-1 -> 0.01771057 | T15: =T10/S10-1 -> 0.11382538 | W15: =W10/T10-1 -> -0.10049769 | X15: =X10/W10-1 -> -0.031263961 | Y15: =Y10/X10-1 -> 0.0044634507 | Z15: =Z10/Y10-1 -> 0.041217971 | AC15: =AC10/Z10-1 -> -0.055174959 | AD15: =AD10/AC10-1 -> -0.081647462 | AE15: =AE10/AD10-1 -> -0.17492481 | AF15: =AF10/AE10-1 -> -0.29099072 | AI15: =AI10/AF10-1 -> -0.62815398 | AJ15: =AJ10/AI10-1 -> 0.50633084 | AK15: =AK10/AJ10-1 -> 1.007491 | AL15: =AL10/AK10-1 -> 0.04555245 | AO15: =AO10/AL10-1 -> 0.27771864 | AP15: =AP10/AO10-1 -> 0.44068482 | AQ15: =AQ10/AP10-1 -> 0.10040236 | AR15: =AR10/AQ10-1 -> 0.29370748 | AU15: =AU10/AR10-1 -> -0.045484422 | AV15: =AV10/AU10-1 -> 0.053160722 | AW15: =AW10/AV10-1 -> -0.046358049 | AX15: =AX10/AW10-1 -> -0.16976346 | BA15: =BA10/AX10-1 -> 0.033859113 | BB15: =BB10/BA10-1 -> -0.019330617 | BC15: =BC10/BB10-1 -> 0.00089598436 | BD15: =BD10/BC10-1 -> -0.16739909 | BG15: =BG10/BD10-1 -> -0.12804222 | BH15: =BH10/BG10-1 -> 0.36610245 | BI15: =BI10/BH10-1 -> 0.14236481 | BJ15: =BJ10/BI10-1 -> 0.38076426 | BM15: =BM10/BJ10-1 -> -0.2735265 | BN15: =BN10/BM10-1 -> 0.17694236 | BO15: =BO10/BN10-1 -> -0.19554636 | BP15: =BP10/BO10-1 -> 0.12993496 | BS15: =BS10/BP10-1 -> 0.10435074 | BT15: =BT10/BS10-1 -> 0.0025456088 | BU15: =BU10/BT10-1 -> -0.063418173 | BV15: =BV10/BU10-1 -> -0.074231862 | BY15: =BY10/BV10-1 -> -0.070422535 | BZ15: =BZ10/BY10-1 -> 0.30483048 | CA15: =CA10/BZ10-1 -> 0.043113359 | CB15: =CB10/CA10-1 -> 0.051140747 | CE15: =CE10/CB10-1 -> 0.018978714 | CF15: =CF10/CE10-1 -> 0.081189545 | CG15: =CG10/CF10-1 -> 0.16465214 | CH15: =CH10/CG10-1 -> 0.046171447 | CK15: =CK10/CH10-1 -> -0.10756132 | CL15: =CL10/CK10-1 -> 0.19929978 | CM15: =CM10/CL10-1 -> 0.013027295 | CN15: =CN10/CM10-1 -> 0.13198372 | CQ15: =CQ10/CN10-1 -> -0.2906603 | CR15: =CR10/CQ10-1 -> 0.15198959 | CS15: =CS10/CR10-1 -> 0.16301258 | CT15: =CT10/CS10-1 -> 0.35154864 | CW15: =CW10/CT10-1 -> -0.39535229 | CX15: =CX10/CW10-1 -> 0.36265672 | CY15: =CY10/CX10-1 -> 0.19012539 | CZ15: =CZ10/CY10-1 -> 0.07481051 | DC15: =DC10/CZ10-1 -> 0.025810395 | DD15: =DD10/DC10-1 -> -0.078759825 | DE15: =DE10/DD10-1 -> 0.30374111 | DF15: =DF10/DE10-1 -> -0.048785607 | DI15: =DI10/DF10-1 -> -0.29107831 | DJ15: =DJ10/DI10-1 -> 0.53647012 | DK15: =DK10/DJ10-1 -> 0.064045668 | DL15: =DL10/DK10-1 -> 0.11281865 | DO15: =DO10/DL10-1 -> 0.049143106 | DP15: =DP10/DO10-1 -> 0.023138952 | DQ15: =DQ10/DP10-1 -> -0.03322081 | DR15: =DR10/DQ10-1 -> 0.084519706 | DU15: =DU10/DR10-1 -> -0.26903413 | DV15: =DV10/DS10-1 -> -0.77347098 | DW15: =DW10/DV10-1 -> 0.19614596 | DX15: =DX10/DW10-1 -> 0.24044835 | EA15: =EA10/DX10-1 -> -0.1642376 | EB15: =EB10/DY10-1 -> -0.72785171 | EC15: =EC10/EB10-1 -> -0.022842805 | ED15: =ED10/EC10-1 -> 0.29297499 | EG15: =EG10/ED10-1 -> -0.097911093 | EH15: =EH10/EG10-1 -> -0.048719557 | EI15: =EI10/EH10-1 -> 0.2162146 | EJ15: =EJ10/EI10-1 -> 0.027872319
B17: Growth y/y
B18: System sales | N18: =N8/H8-1 -> -0.35757686 | O18: =O8/I8-1 -> 0.024263095 | Q18: =Q8/K8-1 -> -0.12502709 | R18: =R8/L8-1 -> 0.23552534 | S18: =S8/M8-1 -> 0.8661676 | T18: =T8/N8-1 -> 1.1459529 | U18: =U8/O8-1 -> 0.44952053 | W18: =W8/Q8-1 -> 0.55296772 | X18: =X8/R8-1 -> -0.017839792 | Y18: =Y8/S8-1 -> -0.015555317 | Z18: =Z8/T8-1 -> -0.12851845 | AA18: =AA8/U8-1 -> 0.046996886 | AC18: =AC8/W8-1 -> -0.045360138 | AD18: =AD8/X8-1 -> -0.12137193 | AE18: =AE8/Y8-1 -> -0.29945377 | AF18: =AF8/Z8-1 -> -0.55387513 | AG18: =AG8/AA8-1 -> -0.25557697 | AI18: =AI8/AC8-1 -> -0.87670521 | AJ18: =AJ8/AD8-1 -> -0.74743311 | AK18: =AK8/AE8-1 -> -0.22350916 | AL18: =AL8/AF8-1 -> 0.13494504 | AM18: =AM8/AG8-1 -> -0.5331865 | AO18: =AO8/AI8-1 -> 5.2472799 | AP18: =AP8/AJ8-1 -> 4.0365876 | AQ18: =AQ8/AK8-1 -> 1.2389801 | AR18: =AR8/AL8-1 -> 2.0409349 | AS18: =AS8/AM8-1 -> 2.3150389 | AU18: =AU8/AO8-1 -> 1.0335655 | AV18: =AV8/AP8-1 -> 0.44485374 | AW18: =AW8/AQ8-1 -> 0.23972736 | AX18: =AX8/AR8-1 -> -0.24400274 | AY18: =AY8/AS8-1 -> 0.25398619 | BA18: =BA8/AU8-1 -> -0.18249766 | BB18: =BB8/AV8-1 -> -0.26154769 | BC18: =BC8/AW8-1 -> -0.21434182 | BD18: =BD8/AX8-1 -> -0.2278634 | BE18: =BE8/AY8-1 -> -0.22160568 | BG18: =BG8/BA8-1 -> -0.35533333 | BH18: =BH8/BB8-1 -> -0.070369618 | BI18: =BI8/BC8-1 -> -0.040787764 | BJ18: =BJ8/BD8-1 -> 0.88023483 | BK18: =BK8/BE8-1 -> 0.050373527 | BM18: =BM8/BG8-1 -> 0.52164278 | BN18: =BN8/BH8-1 -> 0.35772802 | BO18: =BO8/BI8-1 -> -0.078165711 | BP18: =BP8/BJ8-1 -> -0.24694699 | BQ18: =BQ8/BK8-1 -> 0.062532869 | BS18: =BS8/BM8-1 -> 0.21019417 | BT18: =BT8/BN8-1 -> -0.087288817 | BU18: =BU8/BO8-1 -> 0.10265687 | BV18: =BV8/BP8-1 -> -0.18833502 | BW18: =BW8/BQ8-1 -> -0.0013198831 | BY18: =BY8/BS8-1 -> -0.31022864 | BZ18: =BZ8/BT8-1 -> 0.11538123 | CA18: =CA8/BU8-1 -> 0.28955193 | CB18: =CB8/BV8-1 -> 0.46338972 | CC18: =CC8/BW8-1 -> 0.10261493 | CE18: =CE8/BY8-1 -> 0.41404978 | CF18: =CF8/BZ8-1 -> 0.093804331 | CG18: =CG8/CA8-1 -> 0.44621134 | CH18: =CH8/CB8-1 -> 0.51648437 | CI18: =CI8/CC8-1 -> 0.36423373 | CK18: =CK8/CE8-1 -> 0.37168942 | CL18: =CL8/CF8-1 -> 0.50747778 | CM18: =CM8/CG8-1 -> 0.14387817 | CN18: =CN8/CH8-1 -> 0.24011458 | CO18: =CO8/CI8-1 -> 0.29580934 | CQ18: =CQ8/CK8-1 -> 0.012772081 | CR18: =CR8/CL8-1 -> -0.11296429 | CS18: =CS8/CM8-1 -> 0.11775449 | CT18: =CT8/CN8-1 -> 0.29138308 | CU18: =CU8/CO8-1 -> 0.089234905 | CW18: =CW8/CQ8-1 -> -0.062166963 | CX18: =CX8/CR8-1 -> 0.31759239 | CY18: =CY8/CS8-1 -> 0.33109735 | CZ18: =CZ8/CT8-1 -> 0.021592615 | DA18: =DA8/CU8-1 -> 0.14677471 | DC18: =DC8/CW8-1 -> 0.97525253 | DD18: =DD8/CX8-1 -> 0.20954646 | DE18: =DE8/CY8-1 -> 0.32804626 | DF18: =DF8/CZ8-1 -> 0.082825251 | DG18: =DG8/DA8-1 -> 0.32338487 | DI18: =DI8/DC8-1 -> -0.26898491 | DJ18: =DJ8/DD8-1 -> 0.40374966 | DK18: =DK8/DE8-1 -> 0.034929824 | DL18: =DL8/DF8-1 -> 0.3709575 | DM18: =DM8/DG8-1 -> 0.13020135 | DO18: =DO8/DI8-1 -> 1.3355194 | DP18: =DP8/DJ8-1 -> 0.35396691 | DQ18: =DQ8/DK8-1 -> 0.24760853 | DR18: =DR8/DL8-1 -> 0.19684492 | DS18: =DS8/DM8-1 -> 0.421787 | DU18: =DU8/DO8-1 -> -0.25757235 | DV18: =DV8/DP8-1 -> -0.15076435 | DW18: =DW8/DQ8-1 -> 0.11638597 | DX18: =DX8/DR8-1 -> 0.25224813 | DY18: =DY8/DS8-1 -> -0.007744341 | EA18: =EA8/DU8-1 -> 0.44743942 | EB18: =EB8/DV8-1 -> 0.17542902 | EC18: =EC8/DW8-1 -> -0.062807965 | ED18: =ED8/DX8-1 -> 0.065782262 | EE18: =EE8/DY8-1 -> 0.12428854 | EG18: =EG8/EA8-1 -> 0.093826214 | EH18: =EH8/EB8-1 -> 0.048944801 | EI18: =EI8/EC8-1 -> 0.4278512 | EJ18: =EJ8/ED8-1 -> 0.09414491 | EK18: =EK8/EE8-1 -> 0.15946094 | EL18: =EL8/FN8-1 -> 0.32001812 | ES18: =ES8/ER8-1 -> 0.024263095 | ET18: =ET8/ES8-1 -> 0.44952053 | EU18: =EU8/ET8-1 -> 0.046996886 | EV18: =EV8/EU8-1 -> -0.25557697 | EW18: =EW8/EV8-1 -> -0.5331865 | EX18: =EX8/EW8-1 -> 2.3150389 | EY18: =EY8/EX8-1 -> 0.25398619 | EZ18: =EZ8/EY8-1 -> -0.22160568 | ... FR18: =FR8/FQ8-1 -> 0.23347599
B19: Field option and service sales | N19: =N9/H9-1 -> 0.2194416 | O19: =O9/I9-1 -> 0.037250102 | Q19: =Q9/K9-1 -> 0.45187934 | R19: =R9/L9-1 -> 0.22006261 | S19: =S9/M9-1 -> 0.37372743 | T19: =T9/N9-1 -> -0.031746723 | U19: =U9/O9-1 -> 0.22154808 | W19: =W9/Q9-1 -> 0.32777989 | X19: =X9/R9-1 -> 0.034358065 | Y19: =Y9/S9-1 -> -0.10537216 | Z19: =Z9/T9-1 -> 0.34999325 | AA19: =AA9/U9-1 -> 0.13277397 | AC19: =AC9/W9-1 -> -0.020464979 | AD19: =AD9/X9-1 -> 0.13568316 | AE19: =AE9/Y9-1 -> 0.16049681 | AF19: =AF9/Z9-1 -> -0.055878997 | AG19: =AG9/AA9-1 -> 0.048001343 | AI19: =AI9/AC9-1 -> -0.16827921 | AJ19: =AJ9/AD9-1 -> -0.2127839 | AK19: =AK9/AE9-1 -> -0.086877186 | AL19: =AL9/AF9-1 -> 0.31233128 | AM19: =AM9/AG9-1 -> -0.035961064 | AO19: =AO9/AI9-1 -> 0.33535292 | AP19: =AP9/AJ9-1 -> 0.56094321 | AQ19: =AQ9/AK9-1 -> 0.5427465 | AR19: =AR9/AL9-1 -> 0.40026083 | AS19: =AS9/AM9-1 -> 0.45582317 | AU19: =AU9/AO9-1 -> 0.52268603 | AV19: =AV9/AP9-1 -> 0.34385724 | AW19: =AW9/AQ9-1 -> 0.24362416 | AX19: =AX9/AR9-1 -> 0.047527604 | AY19: =AY9/AS9-1 -> 0.25097847 | BA19: =BA9/AU9-1 -> 0.20321812 | BB19: =BB9/AV9-1 -> 0.24055158 | BC19: =BC9/AW9-1 -> 0.23313546 | BD19: =BD9/AX9-1 -> 0.17598533 | BE19: =BE9/AY9-1 -> 0.21222787 | BG19: =BG9/BA9-1 -> 0.065874195 | BH19: =BH9/BB9-1 -> 0.11650885 | BI19: =BI9/BC9-1 -> 0.56980306 | BJ19: =BJ9/BD9-1 -> 0.58651598 | BK19: =BK9/BE9-1 -> 0.34659641 | BM19: =BM9/BG9-1 -> 0.70306691 | BN19: =BN9/BH9-1 -> 0.47713864 | BO19: =BO9/BI9-1 -> 0.22023975 | BP19: =BP9/BJ9-1 -> 0.0039302383 | BQ19: =BQ9/BK9-1 -> 0.28853218 | BS19: =BS9/BM9-1 -> 0.10068213 | BT19: =BT9/BN9-1 -> 0.29705442 | BU19: =BU9/BO9-1 -> 0.31117204 | BV19: =BV9/BP9-1 -> 0.35380475 | BW19: =BW9/BQ9-1 -> 0.27065386 | BY19: =BY9/BS9-1 -> 0.17352504 | BZ19: =BZ9/BT9-1 -> -0.087374904 | CA19: =CA9/BU9-1 -> -0.029621885 | CB19: =CB9/BV9-1 -> 0.11747696 | CC19: =CC9/BW9-1 -> 0.035411179 | CE19: =CE9/BY9-1 -> 0.5373891 | CF19: =CF9/BZ9-1 -> 0.51265289 | CG19: =CG9/CA9-1 -> 0.12856886 | CH19: =CH9/CB9-1 -> -0.020701925 | CI19: =CI9/CC9-1 -> 0.26205954 | CK19: =CK9/CE9-1 -> -0.15182743 | CL19: =CL9/CF9-1 -> -0.088387007 | CM19: =CM9/CG9-1 -> 0.10660302 | CN19: =CN9/CH9-1 -> 0.18612717 | CO19: =CO9/CI9-1 -> 0.0021649061 | CQ19: =CQ9/CK9-1 -> -0.12506075 | CR19: =CR9/CL9-1 -> 0.096650864 | CS19: =CS9/CM9-1 -> -0.049748382 | CT19: =CT9/CN9-1 -> 0.26106934 | CU19: =CU9/CO9-1 -> 0.05173377 | CW19: =CW9/CQ9-1 -> 0.58600259 | CX19: =CX9/CR9-1 -> 0.23706596 | CY19: =CY9/CS9-1 -> 0.30488727 | CZ19: =CZ9/CT9-1 -> 0.16572817 | DA19: =DA9/CU9-1 -> 0.29679864 | DC19: =DC9/CW9-1 -> 0.44186318 | DD19: =DD9/CX9-1 -> 0.20685379 | DE19: =DE9/CY9-1 -> 0.31052876 | DF19: =DF9/CZ9-1 -> 0.44193976 | DG19: =DG9/DA9-1 -> 0.35402387 | DI19: =DI9/DC9-1 -> 0.0097967776 | DJ19: =DJ9/DD9-1 -> 0.20493181 | DK19: =DK9/DE9-1 -> 0.34807999 | DL19: =DL9/DF9-1 -> 0.10503153 | DM19: =DM9/DG9-1 -> 0.15828006 | DO19: =DO9/DI9-1 -> 0.12604233 | DP19: =DP9/DJ9-1 -> 0.0048062016 | DQ19: =DQ9/DK9-1 -> -0.10422683 | DR19: =DR9/DL9-1 -> -0.075967426 | DS19: =DS9/DM9-1 -> -0.021451829 | DU19: =DU9/DO9-1 -> -0.057177442 | DV19: =DV9/DP9-1 -> 0.14326493 | DW19: =DW9/DQ9-1 -> 0.12932298 | DX19: =DX9/DR9-1 -> 0.38108717 | DY19: =DY9/DS9-1 -> 0.15557216 | EA19: =EA9/DU9-1 -> 0.51129069 | EB19: =EB9/DV9-1 -> 0.41413051 | EC19: =EC9/DW9-1 -> 0.27308117 | ED19: =ED9/DX9-1 -> -0.0060086637 | EE19: =EE9/DY9-1 -> 0.26157186 | EG19: =EG9/EA9-1 -> 0.24306631 | EH19: =EH9/EB9-1 -> 0.17837374 | EI19: =EI9/EC9-1 -> 0.1275609 | EJ19: =EJ9/ED9-1 -> -0.0031865042 | EK19: =EK9/EE9-1 -> 0.1347142 | EL19: =EL9/FN9-1 -> 0.13523224 | ES19: =ES9/ER9-1 -> 0.037250102 | ET19: =ET9/ES9-1 -> 0.22154808 | EU19: =EU9/ET9-1 -> 0.13277397 | EV19: =EV9/EU9-1 -> 0.048001343 | EW19: =EW9/EV9-1 -> -0.035961064 | EX19: =EX9/EW9-1 -> 0.45582317 | EY19: =EY9/EX9-1 -> 0.25097847 | EZ19: =EZ9/EY9-1 -> 0.21222787 | ... FR19: =FR9/FQ9-1 -> -1
B20: Total y/y | K20: =K10/E10-1 -> 0.50981841 | L20: =L10/F10-1 -> 0.23854782 | M20: =M10/G10-1 -> -0.12665446 | N20: =N10/H10-1 -> -0.30222171 | O20: =O10/I10-1 -> 0.025793215 | Q20: =Q10/K10-1 -> -0.080753053 | R20: =R10/L10-1 -> 0.23384932 | S20: =S10/M10-1 -> 0.79766971 | T20: =T10/N10-1 -> 0.94850776 | U20: =U10/O10-1 -> 0.42236099 | W20: =W10/Q10-1 -> 0.52567248 | X20: =X10/R10-1 -> -0.012245236 | Y20: =Y10/S10-1 -> -0.025102433 | Z20: =Z10/T10-1 -> -0.088653495 | AA20: =AA10/U10-1 -> 0.0557732 | AC20: =AC10/W10-1 -> -0.042733975 | AD20: =AD10/X10-1 -> -0.092520925 | AE20: =AE10/Y10-1 -> -0.25458863 | AF20: =AF10/Z10-1 -> -0.49241793 | AG20: =AG10/AA10-1 -> -0.22225089 | AI20: =AI10/AC10-1 -> -0.80023564 | AJ20: =AJ10/AD10-1 -> -0.67233583 | AK20: =AK10/AE10-1 -> -0.20276011 | AL20: =AL10/AF10-1 -> 0.1756632 | AM20: =AM10/AG10-1 -> -0.45963541 | AO20: =AO10/AI10-1 -> 3.0397549 | AP20: =AP10/AJ10-1 -> 2.8637021 | AQ20: =AQ10/AK10-1 -> 1.117881 | AR20: =AR10/AL10-1 -> 1.6205462 | AS20: =AS10/AM10-1 -> 1.8243873 | AU20: =AU10/AO10-1 -> 0.95767053 | AV20: =AV10/AP10-1 -> 0.4310845 | AW20: =AW10/AQ10-1 -> 0.24022109 | AX20: =AX10/AR10-1 -> -0.20408834 | AY20: =AY10/AS10-1 -> 0.25357705 | BA20: =BA10/AU10-1 -> -0.13792866 | BB20: =BB10/AV10-1 -> -0.1972669 | BC20: =BC10/AW10-1 -> -0.15749057 | BD20: =BD10/AX10-1 -> -0.15509125 | BE20: =BE10/AY10-1 -> -0.16271456 | BG20: =BG10/BA10-1 -> -0.28740315 | BH20: =BH10/BB10-1 -> -0.0073307811 | BI20: =BI10/BC10-1 -> 0.13297526 | BJ20: =BJ10/BD10-1 -> 0.87889747 | BK20: =BK10/BE10-1 -> 0.14663426 | BM20: =BM10/BG10-1 -> 0.56540747 | BN20: =BN10/BH10-1 -> 0.3486502 | BO20: =BO10/BI10-1 -> -0.050280132 | BP20: =BP10/BJ10-1 -> -0.22280601 | BQ20: =BQ10/BK10-1 -> 0.079442611 | BS20: =BS10/BM10-1 -> 0.18145363 | BT20: =BT10/BN10-1 -> 0.0063884157 | BU20: =BU10/BO10-1 -> 0.17168356 | BV20: =BV10/BP10-1 -> -0.040026774 | BW20: =BW10/BQ10-1 -> 0.073613032 | BY20: =BY10/BS10-1 -> -0.19195103 | BZ20: =BZ10/BT10-1 -> 0.051689741 | CA20: =CA10/BU10-1 -> 0.17131423 | CB20: =CB10/BV10-1 -> 0.32994004 | CC20: =CC10/BW10-1 -> 0.080701085 | CE20: =CE10/BY10-1 -> 0.45784578 | CF20: =CF10/BZ10-1 -> 0.20797885 | CG20: =CG10/CA10-1 -> 0.34872699 | CH20: =CH10/CB10-1 -> 0.34235084 | CI20: =CI10/CC10-1 -> 0.33231295 | CK20: =CK10/CE10-1 -> 0.17565343 | CL20: =CL10/CF10-1 -> 0.30408299 | CM20: =CM10/CG10-1 -> 0.13430579 | CN20: =CN10/CH10-1 -> 0.22734729 | CO20: =CO10/CI10-1 -> 0.20890774 | CQ20: =CQ10/CK10-1 -> -0.024463895 | CR20: =CR10/CL10-1 -> -0.062947015 | CS20: =CS10/CM10-1 -> 0.075789777 | CT20: =CT10/CN10-1 -> 0.28445505 | CU20: =CU10/CO10-1 -> 0.080034722 | CW20: =CW10/CQ10-1 -> 0.094881342 | CX20: =CX10/CR10-1 -> 0.29510495 | CY20: =CY10/CS10-1 -> 0.32529717 | CZ20: =CZ10/CT10-1 -> 0.053934199 | DA20: =DA10/CU10-1 -> 0.18261576 | DC20: =DC10/CW10-1 -> 0.78804392 | DD20: =DD10/CX10-1 -> 0.20882822 | DE20: =DE10/CY10-1 -> 0.32422941 | DF20: =DF10/CZ10-1 -> 0.17195176 | DG20: =DG10/DA10-1 -> 0.33141132 | DI20: =DI10/DC10-1 -> -0.19008227 | DJ20: =DJ10/DD10-1 -> 0.35080344 | DK20: =DK10/DE10-1 -> 0.1024555 | DL20: =DL10/DF10-1 -> 0.28975449 | DM20: =DM10/DG10-1 -> 0.13768202 | DO20: =DO10/DI10-1 -> 0.90872567 | DP20: =DP10/DJ10-1 -> 0.27102477 | DQ20: =DQ10/DK10-1 -> 0.15483793 | DR20: =DR10/DL10-1 -> 0.12547044 | DS20: =DS10/DM10-1 -> 0.30156234 | DU20: =DU10/DO10-1 -> -0.21585485 | DV20: =DV10/DP10-1 -> -0.095547861 | DW20: =DW10/DQ10-1 -> 0.11903192 | DX20: =DX10/DR10-1 -> 0.27992262 | DY20: =DY10/DS10-1 -> 0.025560172 | EA20: =EA10/DU10-1 -> 0.46342155 | EB20: =EB10/DV10-1 -> 0.23209137 | EC20: =EC10/DW10-1 -> 0.0065217682 | ED20: =ED10/DX10-1 -> 0.049142808 | EE20: =EE10/DY10-1 -> 0.15583327 | EG20: =EG10/EA10-1 -> 0.13240328 | EH20: =EH10/EB10-1 -> 0.084207652 | EI20: =EI10/EC10-1 -> 0.3494545 | EJ20: =EJ10/ED10-1 -> 0.072771661 | EK20: =EK10/EE10-1 -> 0.15325449 | EL20: =EL10/FN10-1 -> 0.27441906 | EZ20: =EZ10/EY10-1 -> -0.16271456 | FA20: =FA10/EZ10-1 -> 0.10859136 | FB20: =FB10/FA10-1 -> 0.11648523 | FC20: =FC10/FB10-1 -> 0.073613032 | FD20: =FD10/FC10-1 -> 0.080701085 | FE20: =FE10/FD10-1 -> 0.33231295 | FF20: =FF10/FE10-1 -> 0.20890774 | FG20: =FG10/FF10-1 -> 0.080034722 | ... FR20: =FR10/FQ10-1 -> 0.17176736
A22: INSTALLED BASE MANAGEMENT | E22: =E$3 -> 1Q04 | F22: =F$3 -> 2Q04 | G22: =G$3 -> 3Q04 | H22: =H$3 -> 4Q04 | I22: =I$3 -> 2004 | K22: =K$3 -> 1Q05 | L22: =L$3 -> 2Q05 | M22: =M$3 -> 3Q05 | N22: =N$3 -> 4Q05 | O22: =O$3 -> 2005 | Q22: =Q$3 -> 1Q06 | R22: =R$3 -> 2Q06 | S22: =S$3 -> 3Q06 | T22: =T$3 -> 4Q06 | U22: =U$3 -> 2006 | W22: =W$3 -> 1Q07 | X22: =X$3 -> 2Q07 | Y22: =Y$3 -> 3Q07 | Z22: =Z$3 -> 4Q07 | AA22: =AA$3 -> 2007 | AC22: =AC$3 -> 1Q08 | AD22: =AD$3 -> 2Q08 | AE22: =AE$3 -> 3Q08 | AF22: =AF$3 -> 4Q08 | AG22: =AG$3 -> 2008 | AI22: =AI$3 -> 1Q09 | AJ22: =AJ$3 -> 2Q09 | AK22: =AK$3 -> 3Q09 | AL22: =AL$3 -> 4Q09 | AM22: =AM$3 -> 2009 | AO22: =AO$3 -> 1Q10 | AP22: =AP$3 -> 2Q10 | AQ22: =AQ$3 -> 3Q10 | AR22: =AR$3 -> 4Q10 | AS22: =AS$3 -> 2010 | AU22: =AU$3 -> 1Q11 | AV22: =AV$3 -> 2Q11 | AW22: =AW$3 -> 3Q11 | AX22: =AX$3 -> 4Q11 | AY22: =AY$3 -> 2011 | BA22: =BA$3 -> 1Q12 | BB22: =BB$3 -> 2Q12 | BC22: =BC$3 -> 3Q12 | BD22: =BD$3 -> 4Q12 | BE22: =BE$3 -> 2012 | BG22: =BG$3 -> 1Q13 | BH22: =BH$3 -> 2Q13 | BI22: =BI$3 -> 3Q13 | BJ22: =BJ$3 -> 4Q13 | BK22: =BK$3 -> 2013 | BM22: =BM$3 -> 1Q14 | BN22: =BN$3 -> 2Q14 | BO22: =BO$3 -> 3Q14 | BP22: =BP$3 -> 4Q14 | BQ22: =BQ$3 -> 2014 | BS22: =BS$3 -> 1Q15 | BT22: =BT$3 -> 2Q15 | BU22: =BU$3 -> 3Q15 | BV22: =BV$3 -> 4Q15 | BW22: =BW$3 -> 2015 | BY22: =BY$3 -> 1Q16 | BZ22: =BZ$3 -> 2Q16 | CA22: =CA$3 -> 3Q16 | CB22: =CB$3 -> 4Q16 | CC22: =CC$3 -> 2016 | CE22: =CE$3 -> 1Q17 | CF22: =CF$3 -> 2Q17 | CG22: =CG$3 -> 3Q17 | CH22: =CH$3 -> 4Q17 | CI22: =CI$3 -> 2017 | CK22: =CK$3 -> 1Q18 | CL22: =CL$3 -> 2Q18 | CM22: =CM$3 -> 3Q18 | CN22: =CN$3 -> 4Q18 | CO22: =CO$3 -> 2018
B24: High NA - installled units | DU24: 0 | DV24: 0 | DW24: 0 | DX24: 0 | DY24: =DX24 -> 0 | EA24: 0 | EB24: 0 | EC24: =EB24+EC73 -> 1 | ED24: =EC24+ED73 -> 3 | EE24: =ED24 -> 3 | EG24: =ED24+EG73 -> 5 | EH24: =EG24+EH73 -> 5 | EI24: =EH24+EI73 -> 7 | EJ24: =EI24+EJ73 -> 9 | EK24: =EJ24 -> 9 | EL24: =EK24+EL73 -> 15 | FE24: =CI24 -> 0 | FF24: =CO24 -> 0 | FG24: =CU24 -> 0 | FH24: =DA24 -> 0 | FI24: =DG24 -> 0 | FJ24: =DM24 -> 0 | FK24: =DS24 -> 0 | FL24: =DY24 -> 0 | FM24: =EE24 -> 3 | FN24: =EK24 -> 9 | FO24: =EL24 -> 15 | FP24: =FO24+FP73 -> 23 | FQ24: =EN24 -> 0 | FR24: =EO24 -> 0
B25: Low NA - installled units | CE25: =BQ74+BW74+CC74+BK74+CE74 -> 11 | CF25: =CE25+CF74 -> 13 | CG25: =CF25+CG74 -> 17 | CH25: =CG25+CH74 -> 22 | CI25: =CH25 -> 22 | CK25: =CH25+CK74 -> 23 | CL25: =CK25+CL74 -> 30 | CM25: =CL25+CM74 -> 35 | CN25: =CM25+CN74 -> 40 | CO25: =CN25 -> 40 | CQ25: =CN25+CQ74 -> 44 | CR25: =CQ25+CR74 -> 51 | CS25: =CR25+CS74 -> 58 | CT25: =CS25+CT74 -> 66 | CU25: =CT25 -> 66 | CW25: =CT25+CW74 -> 68 | CX25: =CW25+CX74 -> 75 | CY25: =CX25+CY74 -> 89 | CZ25: =CY25+CZ74 -> 97 | DA25: =CZ25 -> 97 | DC25: =CZ25+DC74 -> 104 | DD25: =DC25+DD74 -> 113 | DE25: =DD25+DE74 -> 128 | DF25: =DE25+DF74 -> 139 | DG25: =DF25 -> 139 | DI25: =DF25+DI74 -> 142 | DJ25: =DI25+DJ74 -> 154 | DK25: =DJ25+DK74 -> 166 | DL25: =DK25+DL74 -> 179 | DM25: =DL25 -> 179 | DO25: =DL25+DO74 -> 196 | DP25: =DO25+DP74 -> 208 | DQ25: =DP25+DQ74 -> 219 | DR25: =DQ25+DR74 -> 232 | DS25: =DR25 -> 232 | DU25: =DR25+DU74 -> 243 | DV25: =DS25+DV74 -> 240 | DW25: =DV25+DW74 -> 251 | DX25: =DW25+DX74 -> 263 | DY25: =DX25 -> 263 | EA25: =DX25+EA74 -> 277 | EB25: =DY25+EB74 -> 273 | EC25: =EB25+EC74 -> 281 | ED25: =EC25+ED74 -> 293 | EE25: =ED25 -> 293 | EG25: =ED25+EG74 -> 307 | EH25: =EG25+EH74 -> 321 | EI25: =EH25+EI74 -> 338 | EJ25: =EI25+EJ74 -> 356 | EK25: =EJ25 -> 356 | EL25: =FN25+EL74 -> 440 | FE25: =CI25 -> 22 | FF25: =CO25 -> 40 | FG25: =CU25 -> 66 | FH25: =DA25 -> 97 | FI25: =DG25 -> 139 | FJ25: =DM25 -> 179 | FK25: =DS25 -> 232 | FL25: =DY25 -> 263 | FM25: =EE25 -> 293 | FN25: =EK25 -> 356 | FO25: =EL25 -> 440 | FP25: =GR25+FP74 -> 61 | FQ25: =EN25 -> 0 | FR25: =EO25 -> 0
B26: ArF - installled units | CE26: =31+57+31+94+101+72+77+BQ76+BW76+CC76+BK76+CE76 -> 771 | CF26: =CE26+CF76 -> 787 | CG26: =CF26+CG76 -> 809 | CH26: =CG26+CH76 -> 829 | CI26: =CH26 -> 829 | CK26: =CH26+CK76 -> 850 | CL26: =CK26+CL76 -> 869 | CM26: =CL26+CM76 -> 891 | CN26: =CM26+CN76 -> 915 | CO26: =CN26 -> 915 | CQ26: =CN26+CQ76 -> 932 | CR26: =CQ26+CR76 -> 945 | CS26: =CR26+CS76 -> 966 | CT26: =CS26+CT76 -> 997 | CU26: =CT26 -> 997 | CW26: =CT26+CW76 -> 1013 | CX26: =CW26+CX76 -> 1030 | CY26: =CX26+CY76 -> 1041 | CZ26: =CY26+CZ76 -> 1065 | DA26: =CZ26 -> 1065 | DC26: =CZ26+DC76 -> 1089 | DD26: =DC26+DD76 -> 1105 | DE26: =DD26+DE76 -> 1126 | DF26: =DE26+DF76 -> 1146 | DG26: =DF26 -> 1146 | DI26: =DF26+DI76 -> 1164 | DJ26: =DI26+DJ76 -> 1185 | DK26: =DJ26+DK76 -> 1205 | DL26: =DK26+DL76 -> 1227 | DM26: =DL26 -> 1227 | DO26: =DL26+DO76 -> 1252 | DP26: =DO26+DP76 -> 1291 | DQ26: =DP26+DQ76 -> 1323 | DR26: =DQ26+DR76 -> 1352 | DS26: =DR26 -> 1352 | DU26: =DR26+DU76 -> 1372 | DV26: =DS26+DV76 -> 1384 | DW26: =DV26+DW76 -> 1422 | DX26: =DW26+DX76 -> 1461 | DY26: =DX26 -> 1461 | EA26: =DX26+EA76 -> 1486 | EB26: =EA26+EB76 -> 1517 | EC26: =EB26+EC76 -> 1555 | ED26: =EC26+ED76 -> 1592 | EE26: =ED26 -> 1592 | EG26: =ED26+EG76 -> 1609 | EH26: =EG26+EH76 -> 1635.5 | EI26: =EH26+EI76 -> 1668.5 | EJ26: =EI26+EJ76 -> 1713.5 | EK26: =EJ26 -> 1713.5 | EL26: =FN26+EL76 -> 1868.7815 | FE26: =CI26 -> 829 | FF26: =CO26 -> 915 | FG26: =CU26 -> 997 | FH26: =DA26 -> 1065 | FI26: =DG26 -> 1146 | FJ26: =DM26 -> 1227 | FK26: =DS26 -> 1352 | FL26: =DY26 -> 1461 | FM26: =EE26 -> 1592 | FN26: =EK26 -> 1713.5 | FO26: =EL26 -> 1868.7815 | FP26: =GR26+FP76 -> 0 | FQ26: =EN26 -> 0 | FR26: =EO26 -> 0
B27: Total installed base | CE27: =SUM(CE24:CE26) -> 782 | CF27: =SUM(CF24:CF26) -> 800 | CG27: =SUM(CG24:CG26) -> 826 | CH27: =SUM(CH24:CH26) -> 851 | CI27: =SUM(CI24:CI26) -> 851 | CK27: =SUM(CK24:CK26) -> 873 | CL27: =SUM(CL24:CL26) -> 899 | CM27: =SUM(CM24:CM26) -> 926 | CN27: =SUM(CN24:CN26) -> 955 | CO27: =SUM(CO24:CO26) -> 955 | CQ27: =SUM(CQ24:CQ26) -> 976 | CR27: =SUM(CR24:CR26) -> 996 | CS27: =SUM(CS24:CS26) -> 1024 | CT27: =SUM(CT24:CT26) -> 1063 | CU27: =SUM(CU24:CU26) -> 1063 | CW27: =SUM(CW24:CW26) -> 1081 | CX27: =SUM(CX24:CX26) -> 1105 | CY27: =SUM(CY24:CY26) -> 1130 | CZ27: =SUM(CZ24:CZ26) -> 1162 | DA27: =SUM(DA24:DA26) -> 1162 | DC27: =SUM(DC24:DC26) -> 1193 | DD27: =SUM(DD24:DD26) -> 1218 | DE27: =SUM(DE24:DE26) -> 1254 | DF27: =SUM(DF24:DF26) -> 1285 | DG27: =SUM(DG24:DG26) -> 1285 | DI27: =SUM(DI24:DI26) -> 1306 | DJ27: =SUM(DJ24:DJ26) -> 1339 | DK27: =SUM(DK24:DK26) -> 1371 | DL27: =SUM(DL24:DL26) -> 1406 | DM27: =SUM(DM24:DM26) -> 1406 | DO27: =SUM(DO24:DO26) -> 1448 | DP27: =SUM(DP24:DP26) -> 1499 | DQ27: =SUM(DQ24:DQ26) -> 1542 | DR27: =SUM(DR24:DR26) -> 1584 | DS27: =SUM(DS24:DS26) -> 1584 | DU27: =SUM(DU24:DU26) -> 1615 | DV27: =SUM(DV24:DV26) -> 1624 | DW27: =SUM(DW24:DW26) -> 1673 | DX27: =SUM(DX24:DX26) -> 1724 | DY27: =SUM(DY24:DY26) -> 1724 | EA27: =SUM(EA24:EA26) -> 1763 | EB27: =SUM(EB24:EB26) -> 1790 | EC27: =SUM(EC24:EC26) -> 1837 | ED27: =SUM(ED24:ED26) -> 1888 | EE27: =SUM(EE24:EE26) -> 1888 | EG27: =SUM(EG24:EG26) -> 1921 | EH27: =SUM(EH24:EH26) -> 1961.5 | EI27: =SUM(EI24:EI26) -> 2013.5 | EJ27: =SUM(EJ24:EJ26) -> 2078.5 | EK27: =SUM(EK24:EK26) -> 2078.5 | EL27: =SUM(EL24:EL26) -> 2323.7815 | FE27: =SUM(FE24:FE26) -> 851 | FF27: =SUM(FF24:FF26) -> 955 | FG27: =SUM(FG24:FG26) -> 1063 | FH27: =SUM(FH24:FH26) -> 1162 | FI27: =SUM(FI24:FI26) -> 1285 | FJ27: =SUM(FJ24:FJ26) -> 1406 | FK27: =SUM(FK24:FK26) -> 1584 | FL27: =SUM(FL24:FL26) -> 1724 | ... FR27: =SUM(FR24:FR26) -> 0
B29: High NA - installled units | EG29: 5 | EH29: 5 | EI29: 5 | EJ29: 5 | EK29: =EK34/EE24 -> 0 | EL29: 20 | FE29: =CI29 -> 0 | FF29: =CO29 -> 0 | FG29: =CU29 -> 0 | FH29: =DA29 -> 0 | FI29: =DG29 -> 0 | FJ29: =DM29 -> 0 | FK29: =DS29 -> 0 | FL29: =DY29 -> 0 | FM29: =EE29 -> 0 | FN29: =EK29 -> 0 | FO29: =EL29 -> 20 | FP29: 15 | FQ29: 15 | FR29: 15
B30: Low NA - installled units | CK30: =CK35/CE25 -> 1.4472727 | CL30: =CL35/CF25 -> 3.08 | CM30: =CM35/CG25 -> 3.7929412 | CN30: =CN35/CH25 -> 3.2536364 | CO30: =CO35/CI25 -> 8.7281818 | CQ30: =CQ35/CK25 -> 1.3086957 | CR30: =CR35/CL25 -> 3.6266667 | CS30: =CS35/CM25 -> 1.0628571 | CT30: =CT35/CN25 -> 2.055 | CU30: =CU35/CO25 -> 6.4575 | CW30: =CW35/CQ25 -> 4.6409091 | CX30: =CX35/CR25 -> 4.4235294 | CY30: =CY35/CS25 -> 3.2103448 | CZ30: =CZ35/CT25 -> 2.4015152 | DA30: =DA35/CU25 -> 11.734848 | DC30: =DC35/CW25 -> 6.2455882 | DD30: =DD35/CX25 -> 4.6613333 | DE30: =DE35/CY25 -> 4.511236 | DF30: =DF35/CZ25 -> 5.8134021 | DG30: =DG35/DA25 -> 17.935052 | DI30: =DI35/DC25 -> 4.6625 | DJ30: =DJ35/DD25 -> 4.5707965 | DK30: =DK35/DE25 -> 4.865625 | DL30: =DL35/DF25 -> 4.6827338 | DM30: =DM35/DG25 -> 16.367626 | DO30: =DO35/DI25 -> 3.3323944 | DP30: =DP35/DJ25 -> 3.0305195 | DQ30: =DQ35/DK25 -> 3.1403614 | DR30: =DR35/DL25 -> 2.5150838 | DS30: =DS35/DM25 -> 10.678212 | DU30: =DU35/DO25 -> 2.2841837 | DV30: =DV35/DP25 -> 2.7798077 | DW30: =DW35/DQ25 -> 2.8091324 | DX30: =DX35/DR25 -> 3.4262931 | DY30: =DY35/DS25 -> 10.5 | EA30: =EA35/DU25 -> 4.282716 | EB30: =EB35/DV25 -> 4.695 | EC30: =EC35/DW25 -> 3.8517928 | ED30: =ED35/DX25 -> 4.2254753 | EE30: =EE35/DY25 -> 16.142966 | EG30: =EG35/EA25 -> 4.6884477 | EH30: 4.6 | EI30: 4 | EJ30: 4 | EK30: =EK35/EE25 -> 16.554608 | EL30: 16 | FE30: =CI30 -> 0 | FF30: =CO30 -> 8.7281818 | FG30: =CU30 -> 6.4575 | FH30: =DA30 -> 11.734848 | FI30: =DG30 -> 17.935052 | FJ30: =DM30 -> 16.367626 | FK30: =DS30 -> 10.678212 | FL30: =DY30 -> 10.5 | FM30: =EE30 -> 16.142966 | FN30: =EK30 -> 16.554608 | FO30: =EL30 -> 16 | FP30: 12.5 | FQ30: 12.5 | FR30: 12.5
B31: ArF - installled units | CK31: 0.78 | CL31: 0.78 | CM31: 0.78 | CN31: 0.78 | CO31: =CO36/CI26 -> 3.0070929 | CQ31: 0.6 | CR31: 0.7 | CS31: 0.7 | CT31: 0.9 | CU31: =CU36/CO26 -> 2.8038251 | CW31: 0.7 | CX31: 0.7 | CY31: 0.7 | CZ31: 0.9 | DA31: =DA36/CU26 -> 2.8960883 | DC31: 0.8 | DD31: 0.7 | DE31: 0.7 | DF31: 0.9 | DG31: =DG36/DA26 -> 3.0221596 | DI31: 0.7 | DJ31: 0.7 | DK31: 0.8 | DL31: 0.9 | DM31: =DM36/DG26 -> 3.026178 | DO31: 0.8 | DP31: 0.7 | DQ31: 0.7 | DR31: 0.9 | DS31: =DS36/DM26 -> 3.0224124 | DU31: 0.7 | DV31: 0.7 | DW31: 0.7 | DX31: 1 | DY31: =DY36/DS26 -> 3.0016272 | EA31: 0.7 | EB31: 0.7 | EC31: 0.7 | ED31: 0.7 | EE31: =EE36/DY26 -> 2.7017796 | EG31: 0.8 | EH31: 0.8 | EI31: 0.7 | EJ31: 0.6 | EK31: =EK36/EE26 -> 2.7927764 | EL31: 2.8 | FE31: =CI31 -> 0 | FF31: =CO31 -> 3.0070929 | FG31: =CU31 -> 2.8038251 | FH31: =DA31 -> 2.8960883 | FI31: =DG31 -> 3.0221596 | FJ31: =DM31 -> 3.026178 | FK31: =DS31 -> 3.0224124 | FL31: =DY31 -> 3.0016272 | FM31: =EE31 -> 2.7017796 | FN31: =EK31 -> 2.7927764 | FO31: =EL31 -> 2.8 | FP31: 2.8 | FQ31: 3 | FR31: 3
B32: IBM per installed system | CK32: =CK37/CE27 -> 0.78938619 | CL32: =CL37/CF27 -> 0.817375 | CM32: =CM37/CG27 -> 0.84200969 | CN32: =CN37/CH27 -> 0.8439483 | CO32: =CO37/CI27 -> 3.1549941 | CQ32: =CQ37/CK27 -> 0.61867125 | CR32: =CR37/CL27 -> 0.79766407 | CS32: =CS37/CM27 -> 0.7137149 | CT32: =CT37/CN27 -> 0.94837696 | CU32: =CU37/CO27 -> 2.9568586 | CW32: =CW37/CQ27 -> 0.87766393 | CX32: =CX37/CR27 -> 0.89066265 | CY32: =CY37/CS27 -> 0.8421875 | CZ32: =CZ37/CT27 -> 0.99322672 | DA32: =DA37/CU27 -> 3.444873 | DC32: =DC37/CW27 -> 1.1425532 | DD32: =DD37/CX27 -> 0.96886878 | DE32: =DE37/CY27 -> 1.000177 | DF32: =DF37/CZ27 -> 1.3101549 | DG32: =DG37/DA27 -> 4.2670396 | DI32: =DI37/DC27 -> 1.0454317 | DJ32: =DJ37/DD27 -> 1.0591133 | DK32: =DK37/DE27 -> 1.214992 | DL32: =DL37/DF27 -> 1.3091829 | DM32: =DM37/DG27 -> 4.4693385 | DO32: =DO37/DI27 -> 1.0753446 | DP32: =DP37/DJ27 -> 0.96803585 | DQ32: =DQ37/DK27 -> 0.99547775 | DR32: =DR37/DL27 -> 1.1056188 | DS32: =DS37/DM27 -> 3.9970839 | DU32: =DU37/DO27 -> 0.9144337 | DV32: =DV37/DP27 -> 0.98859239 | DW32: =DW37/DQ27 -> 0.99954604 | DX32: =DX37/DR27 -> 1.3553662 | DY32: =DY37/DS27 -> 4.0998737 | EA32: =EA37/DU27 -> 1.2390712 | EB32: =EB37/DV27 -> 1.2903941 | EC32: =EC37/DW27 -> 1.1728631 | ED32: =ED37/DX27 -> 1.237819 | EE32: =EE37/DY27 -> 4.7522622 | EG32: =EG37/EA27 -> 1.4109472 | EH32: =EH37/EB27 -> 1.3795531 | EI32: =EI37/EC27 -> 1.2044094 | EJ32: =EJ37/ED27 -> 1.1266949 | EK32: =EK37/EE27 -> 4.9240466 | EL32: =EL37/EK27 -> 5.077604 | FE32: =FE9/FE27 -> 3.1481786 | FF32: =FF9/FF27 -> 2.8114136 | FG32: =FG9/FG27 -> 2.656444 | FH32: =FH9/FH27 -> 3.1513769 | FI32: =FI9/FI27 -> 3.8585992 | FJ32: =FJ9/FJ27 -> 4.0847084 | FK32: =FK9/FK27 -> 3.5479167 | FL32: =FL9/FL27 -> 3.7669374 | ... FO32: =FO9/FO27 -> 4.5416491 | FP32: =FP37/FO27 -> 4.7154125 | FQ32: =FQ37/FP27 -> 13.184524 | FR32: =IFERROR(FR37/FQ27,"0") -> 0 | FU32: assume asymptotes in time to c.5k
B34: High NA IBM rev (2 yr warranty) | EG34: =DU24*EG29 -> 0 | EH34: =DV24*EH29 -> 0 | EI34: =DW24*EI29 -> 0 | EJ34: =DX24*EJ29 -> 0 | EK34: =SUM(EG34:EJ34) -> 0 | EL34: =EE24*EL29 -> 60 | FE34: =CI34 -> 0 | FF34: =CO34 -> 0 | FG34: =CU34 -> 0 | FH34: =DA34 -> 0 | FI34: =DG34 -> 0 | FJ34: =DM34 -> 0 | FK34: =DS34 -> 0 | FL34: =DY34 -> 0 | FM34: =EE34 -> 0 | FN34: =EK34 -> 0 | FO34: =EL34 -> 60 | FP34: =FO24*FP29 -> 225 | FQ34: =FP24*FQ29 -> 345 | FR34: =FQ24*FR29 -> 0
B35: Low NA IBM rev (1 yr warranty) | CK35: =CK37-CK36 -> 15.92 | CL35: =CL37-CL36 -> 40.04 | CM35: =CM37-CM36 -> 64.48 | CN35: =CN37-CN36 -> 71.58 | CO35: =CO37-CO36 -> 192.02 | CQ35: =CQ37-CQ36 -> 30.1 | CR35: =CR37-CR36 -> 108.8 | CS35: =CS37-CS36 -> 37.2 | CT35: =CT37-CT36 -> 82.2 | CU35: =CU37-CU36 -> 258.3 | CW35: =CW37-CW36 -> 204.2 | CX35: =CX37-CX36 -> 225.6 | CY35: =CY37-CY36 -> 186.2 | CZ35: =CZ37-CZ36 -> 158.5 | DA35: =DA37-DA36 -> 774.5 | DC35: =DC37-DC36 -> 424.7 | DD35: =DD37-DD36 -> 349.6 | DE35: =DE37-DE36 -> 401.5 | DF35: =DF37-DF36 -> 563.9 | DG35: =DG37-DG36 -> 1739.7 | DI35: =DI37-DI36 -> 484.9 | DJ35: =DJ37-DJ36 -> 516.5 | DK35: =DK37-DK36 -> 622.8 | DL35: =DL37-DL36 -> 650.9 | DM35: =DM37-DM36 -> 2275.1 | DO35: =DO37-DO36 -> 473.2 | DP35: =DP37-DP36 -> 466.7 | DQ35: =DQ37-DQ36 -> 521.3 | DR35: =DR37-DR36 -> 450.2 | DS35: =DS37-DS36 -> 1911.4 | DU35: =DU37-DU36 -> 447.7 | DV35: =DV37-DV36 -> 578.2 | DW35: =DW37-DW36 -> 615.2 | DX35: =DX37-DX36 -> 794.9 | DY35: =DY37-DY36 -> 2436 | EA35: =EA37-EA36 -> 1040.7 | EB35: =EB37-EB36 -> 1126.8 | EC35: =EC37-EC36 -> 966.8 | ED35: =ED37-ED36 -> 1111.3 | EE35: =EE37-EE36 -> 4245.6 | EG35: =EG37-EG36 -> 1298.7 | EH35: =EB25*EH30 -> 1255.8 | EI35: =EC25*EI30 -> 1124 | EJ35: =ED25*EJ30 -> 1172 | EK35: =SUM(EG35:EJ35) -> 4850.5 | EL35: =EK25*EL30 -> 5696 | FE35: =CI35 -> 0 | FF35: =CO35 -> 192.02 | FG35: =CU35 -> 258.3 | FH35: =DA35 -> 774.5 | FI35: =DG35 -> 1739.7 | FJ35: =DM35 -> 2275.1 | FK35: =DS35 -> 1911.4 | FL35: =DY35 -> 2436 | FM35: =EE35 -> 4245.6 | FN35: =EK35 -> 4850.5 | FO35: =EL35 -> 5696 | FP35: =FO25*FP30 -> 5500 | FQ35: =FP25*FQ30 -> 762.5 | FR35: =FQ25*FR30 -> 0
B36: ArF IBM rev (1 year warranty) | CK36: =CE26*CK31 -> 601.38 | CL36: =CF26*CL31 -> 613.86 | CM36: =CG26*CM31 -> 631.02 | CN36: =CH26*CN31 -> 646.62 | CO36: =SUM(CK36:CN36) -> 2492.88 | CQ36: =CK26*CQ31 -> 510 | CR36: =CL26*CR31 -> 608.3 | CS36: =CM26*CS31 -> 623.7 | CT36: =CN26*CT31 -> 823.5 | CU36: =SUM(CQ36:CT36) -> 2565.5 | CW36: =CQ26*CW31 -> 652.4 | CX36: =CR26*CX31 -> 661.5 | CY36: =CS26*CY31 -> 676.2 | CZ36: =CT26*CZ31 -> 897.3 | DA36: =SUM(CW36:CZ36) -> 2887.4 | DC36: =CW26*DC31 -> 810.4 | DD36: =CX26*DD31 -> 721 | DE36: =CY26*DE31 -> 728.7 | DF36: =CZ26*DF31 -> 958.5 | DG36: =SUM(DC36:DF36) -> 3218.6 | DI36: =DC26*DI31 -> 762.3 | DJ36: =DD26*DJ31 -> 773.5 | DK36: =DE26*DK31 -> 900.8 | DL36: =DF26*DL31 -> 1031.4 | DM36: =SUM(DI36:DL36) -> 3468 | DO36: =DI26*DO31 -> 931.2 | DP36: =DJ26*DP31 -> 829.5 | DQ36: =DK26*DQ31 -> 843.5 | DR36: =DL26*DR31 -> 1104.3 | DS36: =SUM(DO36:DR36) -> 3708.5 | DU36: =DO26*DU31 -> 876.4 | DV36: =DP26*DV31 -> 903.7 | DW36: =DQ26*DW31 -> 926.1 | DX36: =DR26*DX31 -> 1352 | DY36: =SUM(DU36:DX36) -> 4058.2 | EA36: =DU26*EA31 -> 960.4 | EB36: =DV26*EB31 -> 968.8 | EC36: =DW26*EC31 -> 995.4 | ED36: =DX26*ED31 -> 1022.7 | EE36: =SUM(EA36:ED36) -> 3947.3 | EG36: =EA26*EG31 -> 1188.8 | EH36: =EB26*EH31 -> 1213.6 | EI36: =EC26*EI31 -> 1088.5 | EJ36: =ED26*EJ31 -> 955.2 | EK36: =SUM(EG36:EJ36) -> 4446.1 | EL36: =EK26*EL31 -> 4797.8 | FE36: =CI36 -> 0 | FF36: =CO36 -> 2492.88 | FG36: =CU36 -> 2565.5 | FH36: =DA36 -> 2887.4 | FI36: =DG36 -> 3218.6 | FJ36: =DM36 -> 3468 | FK36: =DS36 -> 3708.5 | FL36: =DY36 -> 4058.2 | FM36: =EE36 -> 3947.3 | FN36: =EK36 -> 4446.1 | FO36: =EL36 -> 4797.8 | FP36: =FO26*FP31 -> 5232.5881 | FQ36: =FP26*FQ31 -> 0 | FR36: =FQ26*FR31 -> 0
B37: IBM revenue | K37: =K9 -> 52.545 | L37: =L9 -> 82.731 | M37: =M9 -> 74.161 | N37: =N9 -> 91.852 | O37: =K37+L37+M37+N37 -> 301.289 | Q37: =Q9 -> 76.289 | R37: =R9 -> 100.937 | S37: =S9 -> 101.877 | T37: =T9 -> 88.936 | U37: =Q37+R37+S37+T37 -> 368.039 | W37: =W9 -> 101.295 | X37: =X9 -> 104.405 | Y37: =Y9 -> 91.142 | Z37: =Z9 -> 120.063 | AA37: =W37+X37+Y37+Z37 -> 416.905 | AC37: =AC9 -> 99.222 | AD37: =AD9 -> 118.571 | AE37: =AE9 -> 105.77 | AF37: =AF9 -> 113.354 | AG37: =AC37+AD37+AE37+AF37 -> 436.917 | AI37: =AI9 -> 82.525 | AJ37: =AJ9 -> 93.341 | AK37: =AK9 -> 96.581 | AL37: =AL9 -> 148.758 | AM37: =AI37+AJ37+AK37+AL37 -> 421.205 | AO37: =AO9 -> 110.2 | AP37: =AP9 -> 145.7 | AQ37: =AQ9 -> 149 | AR37: =AR9 -> 208.3 | AS37: =AO37+AP37+AQ37+AR37 -> 613.2 | AU37: =AU9 -> 167.8 | AV37: =AV9 -> 195.8 | AW37: =AW9 -> 185.3 | AX37: =AX9 -> 218.2 | AY37: =AU37+AV37+AW37+AX37 -> 767.1 | BA37: =BA9 -> 201.9 | BB37: =BB9 -> 242.9 | BC37: =BC9 -> 228.5 | BD37: =BD9 -> 256.6 | BE37: =BA37+BB37+BC37+BD37 -> 929.9 | BG37: =BG9 -> 215.2 | BH37: =BH9 -> 271.2 | BI37: =BI9 -> 358.7 | BJ37: =BJ9 -> 407.1 | BK37: =BG37+BH37+BI37+BJ37 -> 1252.2 | BM37: =BM9 -> 366.5 | BN37: =BN9 -> 400.6 | BO37: =BO9 -> 437.7 | BP37: =BP9 -> 408.7 | BQ37: =BM37+BN37+BO37+BP37 -> 1613.5 | BS37: =BS9 -> 403.4 | BT37: =BT9 -> 519.6 | BU37: =BU9 -> 573.9 | BV37: =BV9 -> 553.3 | BW37: =BS37+BT37+BU37+BV37 -> 2050.2 | BY37: =BY9 -> 473.4 | BZ37: =BZ9 -> 474.2 | CA37: =CA9 -> 556.9 | CB37: =CB9 -> 618.3 | CC37: =BY37+BZ37+CA37+CB37 -> 2122.8 | CE37: =CE9 -> 727.8 | CF37: =CF9 -> 717.3 | CG37: =CG9 -> 628.5 | CH37: =CH9 -> 605.5 | CI37: =CE37+CF37+CG37+CH37 -> 2679.1 | CK37: =CK9 -> 617.3 | CL37: =CL9 -> 653.9 | CM37: =CM9 -> 695.5 | CN37: =CN9 -> 718.2 | CO37: =CK37+CL37+CM37+CN37 -> 2684.9 | CQ37: =CQ9 -> 540.1 | CR37: =CR9 -> 717.1 | CS37: =CS9 -> 660.9 | CT37: =CT9 -> 905.7 | CU37: =CQ37+CR37+CS37+CT37 -> 2823.8 | CW37: =CW9 -> 856.6 | CX37: =CX9 -> 887.1 | CY37: =CY9 -> 862.4 | CZ37: =CZ9 -> 1055.8 | DA37: =CW37+CX37+CY37+CZ37 -> 3661.9 | DC37: =DC9 -> 1235.1 | DD37: =DD9 -> 1070.6 | DE37: =DE9 -> 1130.2 | DF37: =DF9 -> 1522.4 | DG37: =DC37+DD37+DE37+DF37 -> 4958.3 | DI37: =DI9 -> 1247.2 | DJ37: =DJ9 -> 1290 | DK37: =DK9 -> 1523.6 | DL37: =DL9 -> 1682.3 | DM37: =DI37+DJ37+DK37+DL37 -> 5743.1 | DO37: =DO9 -> 1404.4 | DP37: =DP9 -> 1296.2 | DQ37: =DQ9 -> 1364.8 | DR37: =DR9 -> 1554.5 | DS37: =DO37+DP37+DQ37+DR37 -> 5619.9 | DT37: =DS37/DM37-1 -> -0.021451829 | DU37: =DU9 -> 1324.1 | DV37: =DV9 -> 1481.9 | DW37: =DW9 -> 1541.3 | DX37: =DX9 -> 2146.9 | DY37: =SUM(DU37:DX37) -> 6494.2 | DZ37: =DY37/DS37-1 -> 0.15557216 | EA37: =EA9 -> 2001.1 | EB37: =EB9 -> 2095.6 | EC37: =EC9 -> 1962.2 | ED37: =ED9 -> 2134 | EE37: =SUM(EA37:ED37) -> 8192.9 | EG37: =EG9 -> 2487.5 | EH37: =SUM(EH34:EH36) -> 2469.4 | EI37: =SUM(EI34:EI36) -> 2212.5 | EJ37: =SUM(EJ34:EJ36) -> 2127.2 | EK37: =SUM(EK34:EK36) -> 9296.6 | EL37: =SUM(EL34:EL36) -> 10553.8 | FA37: =BK37 -> 1252.2 | FB37: =BQ37 -> 1613.5 | FC37: =BW37 -> 2050.2 | FD37: =CC37 -> 2122.8 | FE37: =CI37 -> 2679.1 | FF37: =CO37 -> 2684.9 | FG37: =CU37 -> 2823.8 | FH37: =DA37 -> 3661.9 | FI37: =DG37 -> 4958.3 | FJ37: =DM37 -> 5743.1 | FK37: =DS37 -> 5619.9 | FL37: =DY37 -> 6494.2 | FM37: =EE37 -> 8192.9 | FN37: =FN27*FN32 -> 9296.6 | FO37: =FO27*FO32 -> 10553.8 | FP37: =SUM(FP34:FP36) -> 10957.588 | FQ37: =SUM(FQ34:FQ36) -> 1107.5 | FR37: =SUM(FR34:FR36) -> 0
