Workbook

Sheet Assumptions
A1: CN Rail (CNR.TO) — DCF Assumptions
A2: All figures in C$ millions unless noted | F2: Currency: CAD
B4: FY2023A | C4: FY2024A | D4: FY2025A | E4: FY2026E | F4: FY2027E | G4: FY2028E | H4: FY2029E | I4: FY2030E | J4: FY2031E | K4: FY2032E | L4: FY2033E | M4: FY2034E | N4: FY2035E
A5: Revenue
A6: Total Revenue (C$M) | B6: 16811 | C6: 17047 | D6: 17300 | E6: =D6*(1+E7) -> 17646 | F6: =E6*(1+F7) -> 18351.84 | G6: =F6*(1+G7) -> 19177.673 | H6: =G6*(1+H7) -> 20040.668 | I6: =H6*(1+I7) -> 20842.295 | J6: =I6*(1+J7) -> 21571.775 | K6: =J6*(1+K7) -> 22326.787 | L6: =K6*(1+L7) -> 22996.591 | ... N6: =M6*(1+N7) -> 24397.083
A7: Revenue Growth Rate | C7: 0.014 | D7: 0.015 | E7: 0.02 | F7: 0.04 | G7: 0.045 | H7: 0.045 | I7: 0.04 | J7: 0.035 | K7: 0.035 | L7: 0.03 | M7: 0.03 | N7: 0.03
A9: Operating Metrics
A10: Operating Ratio | B10: 0.608 | C10: 0.629 | D10: 0.617 | E10: 0.612 | F10: 0.605 | G10: 0.598 | H10: 0.594 | I10: 0.59 | J10: 0.588 | K10: 0.586 | L10: 0.585 | M10: 0.585 | N10: 0.585
A11: EBIT Margin (1 - OR) | B11: =1-B10 -> 0.392 | C11: =1-C10 -> 0.371 | D11: =1-D10 -> 0.383 | E11: =1-E10 -> 0.388 | F11: =1-F10 -> 0.395 | G11: =1-G10 -> 0.402 | H11: =1-H10 -> 0.406 | I11: =1-I10 -> 0.41 | ... N11: =1-N10 -> 0.415
A13: D&A Assumptions
A14: D&A % of Revenue | B14: 0.1 | C14: 0.103 | D14: 0.1 | E14: 0.098 | F14: 0.096 | G14: 0.095 | H14: 0.094 | I14: 0.093 | J14: 0.092 | K14: 0.092 | L14: 0.092 | M14: 0.092 | N14: 0.092
A16: Capital Expenditure
A17: Capex % of Revenue | B17: 0.19 | C17: 0.21 | D17: 0.196 | E17: 0.16 | F17: 0.17 | G17: 0.175 | H17: 0.178 | I17: 0.18 | J17: 0.18 | K17: 0.18 | L17: 0.18 | M17: 0.18 | N17: 0.18
A19: Tax & Working Capital
A20: Effective Tax Rate | B20: 0.255 | C20: 0.255 | D20: 0.255 | E20: 0.255 | F20: 0.255 | G20: 0.255 | H20: 0.255 | I20: 0.255 | J20: 0.255 | K20: 0.255 | L20: 0.255 | M20: 0.255 | N20: 0.255
A21: Change in NWC % of Rev Growth | B21: 0.02 | C21: 0.02 | D21: 0.02 | E21: 0.02 | F21: 0.02 | G21: 0.02 | H21: 0.02 | I21: 0.02 | J21: 0.02 | K21: 0.02 | L21: 0.02 | M21: 0.02 | N21: 0.02
A23: WACC Inputs
A24: Risk-Free Rate (10Y GoC) | B24: 0.032 | C24: Source: Bank of Canada, Mar 2026
A25: Equity Risk Premium | B25: 0.055 | C25: Source: Damodaran, Jan 2026
A26: Beta (5Y Monthly) | B26: 0.85 | C26: Source: Bloomberg, Mar 2026
A27: Cost of Equity (CAPM) | B27: =B24+B26*B25 -> 0.07875
A28: Pre-Tax Cost of Debt | B28: 0.042 | C28: Source: CN 2025 10-K, weighted avg coupon
A29: Tax Rate for WACC | B29: 0.255 | C29: Source: Canadian statutory rate
A30: After-Tax Cost of Debt | B30: =B28*(1-B29) -> 0.03129
A31: Equity Weight | B31: 0.82 | C31: Source: Market cap / (Market cap + Net debt)
A32: Debt Weight | B32: 0.18 | C32: Source: Net debt / (Market cap + Net debt)
A33: WACC | B33: =B31*B27+B32*B30 -> 0.0702072
A35: Terminal Value
A36: Terminal Growth Rate | B36: 0.025 | C36: Long-term nominal GDP proxy
A38: Share Data
A39: Diluted Shares Outstanding (M) | B39: 620 | C39: Source: CN Q4 2025 press release
A40: Current Share Price (C$) | B40: 141 | C40: Source: TSX, Mar 2026
A41: Net Debt (C$M) | B41: 16500 | C41: Source: CN FY2025 balance sheet (est.)
A42: Minority Interest (C$M) | B42: 0

Sheet DCF Model
A1: CN Rail — Unlevered Free Cash Flow Projection
A2: 10-Year DCF Model · C$ Millions
B4: FY2026E | C4: FY2027E | D4: FY2028E | E4: FY2029E | F4: FY2030E | G4: FY2031E | H4: FY2032E | I4: FY2033E | J4: FY2034E | K4: FY2035E
A5: Projection Year | B5: 1 | C5: 2 | D5: 3 | E5: 4 | F5: 5 | G5: 6 | H5: 7 | I5: 8 | J5: 9 | K5: 10
A7: Revenue
A8: Total Revenue | B8: =Assumptions!E6 -> 17646 | C8: =Assumptions!F6 -> 18351.84 | D8: =Assumptions!G6 -> 19177.673 | E8: =Assumptions!H6 -> 20040.668 | F8: =Assumptions!I6 -> 20842.295 | G8: =Assumptions!J6 -> 21571.775 | H8: =Assumptions!K6 -> 22326.787 | I8: =Assumptions!L6 -> 22996.591 | ... K8: =Assumptions!N6 -> 24397.083
A9: Revenue Growth | B9: =Assumptions!E7 -> 0.02 | C9: =Assumptions!F7 -> 0.04 | D9: =Assumptions!G7 -> 0.045 | E9: =Assumptions!H7 -> 0.045 | F9: =Assumptions!I7 -> 0.04 | G9: =Assumptions!J7 -> 0.035 | H9: =Assumptions!K7 -> 0.035 | I9: =Assumptions!L7 -> 0.03 | ... K9: =Assumptions!N7 -> 0.03
A11: Operating Income
A12: Operating Ratio | B12: =Assumptions!E10 -> 0.612 | C12: =Assumptions!F10 -> 0.605 | D12: =Assumptions!G10 -> 0.598 | E12: =Assumptions!H10 -> 0.594 | F12: =Assumptions!I10 -> 0.59 | G12: =Assumptions!J10 -> 0.588 | H12: =Assumptions!K10 -> 0.586 | I12: =Assumptions!L10 -> 0.585 | ... K12: =Assumptions!N10 -> 0.585
A13: EBIT (Revenue × EBIT Margin) | B13: =B8*(1-B12) -> 6846.648 | C13: =C8*(1-C12) -> 7248.9768 | D13: =D8*(1-D12) -> 7709.4245 | E13: =E8*(1-E12) -> 8136.5112 | F13: =F8*(1-F12) -> 8545.3409 | G13: =G8*(1-G12) -> 8887.5713 | H13: =H8*(1-H12) -> 9243.2899 | I13: =I8*(1-I12) -> 9543.5852 | ... K13: =K8*(1-K12) -> 10124.79
A15: UFCF Build
A16: EBIT | B16: =B13 -> 6846.648 | C16: =C13 -> 7248.9768 | D16: =D13 -> 7709.4245 | E16: =E13 -> 8136.5112 | F16: =F13 -> 8545.3409 | G16: =G13 -> 8887.5713 | H16: =H13 -> 9243.2899 | I16: =I13 -> 9543.5852 | ... K16: =K13 -> 10124.79
A17: Less: Taxes on EBIT | B17: =-B16*Assumptions!E20 -> -1745.8952 | C17: =-C16*Assumptions!F20 -> -1848.4891 | D17: =-D16*Assumptions!G20 -> -1965.9032 | E17: =-E16*Assumptions!H20 -> -2074.8104 | F17: =-F16*Assumptions!I20 -> -2179.0619 | G17: =-G16*Assumptions!J20 -> -2266.3307 | H17: =-H16*Assumptions!K20 -> -2357.0389 | I17: =-I16*Assumptions!L20 -> -2433.6142 | ... K17: =-K16*Assumptions!N20 -> -2581.8213
A18: NOPAT (EBIT × (1-t)) | B18: =B16+B17 -> 5100.7528 | C18: =C16+C17 -> 5400.4877 | D18: =D16+D17 -> 5743.5212 | E18: =E16+E17 -> 6061.7009 | F18: =F16+F17 -> 6366.2789 | G18: =G16+G17 -> 6621.2407 | H18: =H16+H17 -> 6886.251 | I18: =I16+I17 -> 7109.971 | ... K18: =K16+K17 -> 7542.9682
A19: Plus: D&A | B19: =B8*Assumptions!E14 -> 1729.308 | C19: =C8*Assumptions!F14 -> 1761.7766 | D19: =D8*Assumptions!G14 -> 1821.8789 | E19: =E8*Assumptions!H14 -> 1883.8228 | F19: =F8*Assumptions!I14 -> 1938.3334 | G19: =G8*Assumptions!J14 -> 1984.6033 | H19: =H8*Assumptions!K14 -> 2054.0644 | I19: =I8*Assumptions!L14 -> 2115.6864 | ... K19: =K8*Assumptions!N14 -> 2244.5317
A20: Less: Capex | B20: =-B8*Assumptions!E17 -> -2823.36 | C20: =-C8*Assumptions!F17 -> -3119.8128 | D20: =-D8*Assumptions!G17 -> -3356.0927 | E20: =-E8*Assumptions!H17 -> -3567.2389 | F20: =-F8*Assumptions!I17 -> -3751.6131 | G20: =-G8*Assumptions!J17 -> -3882.9195 | H20: =-H8*Assumptions!K17 -> -4018.8217 | I20: =-I8*Assumptions!L17 -> -4139.3864 | ... K20: =-K8*Assumptions!N17 -> -4391.475
A21: Less: Change in NWC | B21: =-Assumptions!E21*(B8-Assumptions!D6) -> -6.92 | C21: =-Assumptions!F21*(C8-B8) -> -14.1168 | D21: =-Assumptions!G21*(D8-C8) -> -16.516656 | E21: =-Assumptions!H21*(E8-D8) -> -17.259906 | F21: =-Assumptions!I21*(F8-E8) -> -16.032534 | G21: =-Assumptions!J21*(G8-F8) -> -14.589606 | H21: =-Assumptions!K21*(H8-G8) -> -15.100243 | I21: =-Assumptions!L21*(I8-H8) -> -13.396072 | J21: =-Assumptions!M21*(J8-I8) -> -13.797955 | K21: =-Assumptions!N21*(K8-J8) -> -14.211893
A23: Unlevered Free Cash Flow (UFCF) | B23: =B18+B19+B20+B21 -> 3999.7808 | C23: =C18+C19+C20+C21 -> 4028.3348 | D23: =D18+D19+D20+D21 -> 4192.7907 | E23: =E18+E19+E20+E21 -> 4361.0248 | F23: =F18+F19+F20+F21 -> 4536.9668 | G23: =G18+G19+G20+G21 -> 4708.3348 | H23: =H18+H19+H20+H21 -> 4906.3935 | I23: =I18+I19+I20+I21 -> 5072.8749 | ... K23: =K18+K19+K20+K21 -> 5381.813
A24: UFCF Margin | B24: =B23/B8 -> 0.22666784 | C24: =C23/C8 -> 0.21950577 | D24: =D23/D8 -> 0.21862876 | E24: =E23/E8 -> 0.21760876 | F24: =F23/F8 -> 0.21768077 | G24: =G23/G8 -> 0.21826367 | H24: =H23/H8 -> 0.21975367 | I24: =I23/I8 -> 0.22059248 | ... K24: =K23/K8 -> 0.22059248
A26: Discounted Cash Flow Valuation
A27: WACC | B27: =Assumptions!B33 -> 0.0702072
A28: Discount Factor | B28: =1/(1+$B$27)^1 -> 0.9343985 | C28: =1/(1+$B$27)^2 -> 0.87310055 | D28: =1/(1+$B$27)^3 -> 0.81582384 | E28: =1/(1+$B$27)^4 -> 0.76230458 | F28: =1/(1+$B$27)^5 -> 0.71229625 | G28: =1/(1+$B$27)^6 -> 0.66556855 | H28: =1/(1+$B$27)^7 -> 0.62190625 | I28: =1/(1+$B$27)^8 -> 0.58110827 | J28: =1/(1+$B$27)^9 -> 0.54298669 | K28: =1/(1+$B$27)^10 -> 0.50736595
A29: PV of UFCF | B29: =B23*B28 -> 3737.3891 | C29: =C23*C28 -> 3517.1413 | D29: =D23*D28 -> 3420.5787 | E29: =E23*E28 -> 3324.4292 | F29: =F23*F28 -> 3231.6644 | G29: =G23*G28 -> 3133.7196 | H29: =H23*H28 -> 3051.3168 | I29: =I23*I28 -> 2947.8895 | ... K29: =K23*K28 -> 2730.5486
A31: Terminal Value Calculation
A32: Terminal Growth Rate (g) | B32: =Assumptions!B36 -> 0.025
A33: Terminal Year UFCF (Year 10) | B33: =K23 -> 5381.813
A34: Terminal Value (Gordon Growth) | B34: =B33*(1+B32)/(B27-B32) -> 122023.89
A35: PV of Terminal Value | B35: =B34*K28 -> 61910.766
A36: TV as % of Enterprise Value | B36: =B35/B41 -> 0.65972999
A38: Valuation Summary
A39: Sum of PV of UFCFs | B39: =SUM(B29:K29) -> 31931.816
A40: PV of Terminal Value | B40: =B35 -> 61910.766
A41: Enterprise Value | B41: =B39+B40 -> 93842.582
A42: Less: Net Debt | B42: =-Assumptions!B41 -> -16500
A43: Less: Minority Interest | B43: =-Assumptions!B42 -> 0
A44: Equity Value | B44: =B41+B42+B43 -> 77342.582
A45: Diluted Shares Outstanding (M) | B45: =Assumptions!B39 -> 620
A46: Implied Share Price (C$) | B46: =B44/B45 -> 124.7461
A48: Current Share Price (C$) | B48: =Assumptions!B40 -> 141
A49: Upside / (Downside) | B49: =B46/B48-1 -> -0.11527589
...

Sheet Sensitivity
A1: CN Rail — Sensitivity Analysis
A3: Implied Share Price (C$)
A4: WACC → | B4: 0.065 | C4: 0.07 | D4: 0.075 | E4: 0.08 | F4: 0.085 | G4: 0.09 | H4: 0.095
A5: Terminal g ↓
A6: 0.015 | B6: =('DCF Model'!B23/(1+B$4)^1+'DCF Model'!C23/(1+B$4)^2+'DCF Model'!D23/(1+B$4)^3+'DCF Model'!E23/(1+B$4)^4+'DCF Model'!F23/(1+B$4)^5+'DCF Model'!G23/(1+B$4)^6+'DCF Model'!H23/(1+B$4)^7+'DCF Model'!I23/(1+B$4)^8+'DCF Model'!J23/(1+B$4)^9+'DCF Model'!K23/(1+B$4)^10+('DCF Model'!K23*(1+$A6)/(B$4-$A6))/(1+B$4)^10-Assumptions!B41)/Assumptions!B39 -> 120.09863 | C6: =('DCF Model'!B23/(1+C$4)^1+'DCF Model'!C23/(1+C$4)^2+'DCF Model'!D23/(1+C$4)^3+'DCF Model'!E23/(1+C$4)^4+'DCF Model'!F23/(1+C$4)^5+'DCF Model'!G23/(1+C$4)^6+'DCF Model'!H23/(1+C$4)^7+'DCF Model'!I23/(1+C$4)^8+'DCF Model'!J23/(1+C$4)^9+'DCF Model'!K23/(1+C$4)^10+('DCF Model'!K23*(1+$A6)/(C$4-$A6))/(1+C$4)^10-Assumptions!B41)/Assumptions!B39 -> 106.37562 | D6: =('DCF Model'!B23/(1+D$4)^1+'DCF Model'!C23/(1+D$4)^2+'DCF Model'!D23/(1+D$4)^3+'DCF Model'!E23/(1+D$4)^4+'DCF Model'!F23/(1+D$4)^5+'DCF Model'!G23/(1+D$4)^6+'DCF Model'!H23/(1+D$4)^7+'DCF Model'!I23/(1+D$4)^8+'DCF Model'!J23/(1+D$4)^9+'DCF Model'!K23/(1+D$4)^10+('DCF Model'!K23*(1+$A6)/(D$4-$A6))/(1+D$4)^10-Assumptions!B41)/Assumptions!B39 -> 94.951081 | E6: =('DCF Model'!B23/(1+E$4)^1+'DCF Model'!C23/(1+E$4)^2+'DCF Model'!D23/(1+E$4)^3+'DCF Model'!E23/(1+E$4)^4+'DCF Model'!F23/(1+E$4)^5+'DCF Model'!G23/(1+E$4)^6+'DCF Model'!H23/(1+E$4)^7+'DCF Model'!I23/(1+E$4)^8+'DCF Model'!J23/(1+E$4)^9+'DCF Model'!K23/(1+E$4)^10+('DCF Model'!K23*(1+$A6)/(E$4-$A6))/(1+E$4)^10-Assumptions!B41)/Assumptions!B39 -> 85.294184 | F6: =('DCF Model'!B23/(1+F$4)^1+'DCF Model'!C23/(1+F$4)^2+'DCF Model'!D23/(1+F$4)^3+'DCF Model'!E23/(1+F$4)^4+'DCF Model'!F23/(1+F$4)^5+'DCF Model'!G23/(1+F$4)^6+'DCF Model'!H23/(1+F$4)^7+'DCF Model'!I23/(1+F$4)^8+'DCF Model'!J23/(1+F$4)^9+'DCF Model'!K23/(1+F$4)^10+('DCF Model'!K23*(1+$A6)/(F$4-$A6))/(1+F$4)^10-Assumptions!B41)/Assumptions!B39 -> 77.025789 | G6: =('DCF Model'!B23/(1+G$4)^1+'DCF Model'!C23/(1+G$4)^2+'DCF Model'!D23/(1+G$4)^3+'DCF Model'!E23/(1+G$4)^4+'DCF Model'!F23/(1+G$4)^5+'DCF Model'!G23/(1+G$4)^6+'DCF Model'!H23/(1+G$4)^7+'DCF Model'!I23/(1+G$4)^8+'DCF Model'!J23/(1+G$4)^9+'DCF Model'!K23/(1+G$4)^10+('DCF Model'!K23*(1+$A6)/(G$4-$A6))/(1+G$4)^10-Assumptions!B41)/Assumptions!B39 -> 69.867875 | H6: =('DCF Model'!B23/(1+H$4)^1+'DCF Model'!C23/(1+H$4)^2+'DCF Model'!D23/(1+H$4)^3+'DCF Model'!E23/(1+H$4)^4+'DCF Model'!F23/(1+H$4)^5+'DCF Model'!G23/(1+H$4)^6+'DCF Model'!H23/(1+H$4)^7+'DCF Model'!I23/(1+H$4)^8+'DCF Model'!J23/(1+H$4)^9+'DCF Model'!K23/(1+H$4)^10+('DCF Model'!K23*(1+$A6)/(H$4-$A6))/(1+H$4)^10-Assumptions!B41)/Assumptions!B39 -> 63.611937
A7: 0.02 | B7: =('DCF Model'!B23/(1+B$4)^1+'DCF Model'!C23/(1+B$4)^2+'DCF Model'!D23/(1+B$4)^3+'DCF Model'!E23/(1+B$4)^4+'DCF Model'!F23/(1+B$4)^5+'DCF Model'!G23/(1+B$4)^6+'DCF Model'!H23/(1+B$4)^7+'DCF Model'!I23/(1+B$4)^8+'DCF Model'!J23/(1+B$4)^9+'DCF Model'!K23/(1+B$4)^10+('DCF Model'!K23*(1+$A7)/(B$4-$A7))/(1+B$4)^10-Assumptions!B41)/Assumptions!B39 -> 131.04268 | C7: =('DCF Model'!B23/(1+C$4)^1+'DCF Model'!C23/(1+C$4)^2+'DCF Model'!D23/(1+C$4)^3+'DCF Model'!E23/(1+C$4)^4+'DCF Model'!F23/(1+C$4)^5+'DCF Model'!G23/(1+C$4)^6+'DCF Model'!H23/(1+C$4)^7+'DCF Model'!I23/(1+C$4)^8+'DCF Model'!J23/(1+C$4)^9+'DCF Model'!K23/(1+C$4)^10+('DCF Model'!K23*(1+$A7)/(C$4-$A7))/(1+C$4)^10-Assumptions!B41)/Assumptions!B39 -> 114.96023 | D7: =('DCF Model'!B23/(1+D$4)^1+'DCF Model'!C23/(1+D$4)^2+'DCF Model'!D23/(1+D$4)^3+'DCF Model'!E23/(1+D$4)^4+'DCF Model'!F23/(1+D$4)^5+'DCF Model'!G23/(1+D$4)^6+'DCF Model'!H23/(1+D$4)^7+'DCF Model'!I23/(1+D$4)^8+'DCF Model'!J23/(1+D$4)^9+'DCF Model'!K23/(1+D$4)^10+('DCF Model'!K23*(1+$A7)/(D$4-$A7))/(1+D$4)^10-Assumptions!B41)/Assumptions!B39 -> 101.81097 | E7: =('DCF Model'!B23/(1+E$4)^1+'DCF Model'!C23/(1+E$4)^2+'DCF Model'!D23/(1+E$4)^3+'DCF Model'!E23/(1+E$4)^4+'DCF Model'!F23/(1+E$4)^5+'DCF Model'!G23/(1+E$4)^6+'DCF Model'!H23/(1+E$4)^7+'DCF Model'!I23/(1+E$4)^8+'DCF Model'!J23/(1+E$4)^9+'DCF Model'!K23/(1+E$4)^10+('DCF Model'!K23*(1+$A7)/(E$4-$A7))/(1+E$4)^10-Assumptions!B41)/Assumptions!B39 -> 90.861277 | F7: =('DCF Model'!B23/(1+F$4)^1+'DCF Model'!C23/(1+F$4)^2+'DCF Model'!D23/(1+F$4)^3+'DCF Model'!E23/(1+F$4)^4+'DCF Model'!F23/(1+F$4)^5+'DCF Model'!G23/(1+F$4)^6+'DCF Model'!H23/(1+F$4)^7+'DCF Model'!I23/(1+F$4)^8+'DCF Model'!J23/(1+F$4)^9+'DCF Model'!K23/(1+F$4)^10+('DCF Model'!K23*(1+$A7)/(F$4-$A7))/(1+F$4)^10-Assumptions!B41)/Assumptions!B39 -> 81.603284 | G7: =('DCF Model'!B23/(1+G$4)^1+'DCF Model'!C23/(1+G$4)^2+'DCF Model'!D23/(1+G$4)^3+'DCF Model'!E23/(1+G$4)^4+'DCF Model'!F23/(1+G$4)^5+'DCF Model'!G23/(1+G$4)^6+'DCF Model'!H23/(1+G$4)^7+'DCF Model'!I23/(1+G$4)^8+'DCF Model'!J23/(1+G$4)^9+'DCF Model'!K23/(1+G$4)^10+('DCF Model'!K23*(1+$A7)/(G$4-$A7))/(1+G$4)^10-Assumptions!B41)/Assumptions!B39 -> 73.674228 | H7: =('DCF Model'!B23/(1+H$4)^1+'DCF Model'!C23/(1+H$4)^2+'DCF Model'!D23/(1+H$4)^3+'DCF Model'!E23/(1+H$4)^4+'DCF Model'!F23/(1+H$4)^5+'DCF Model'!G23/(1+H$4)^6+'DCF Model'!H23/(1+H$4)^7+'DCF Model'!I23/(1+H$4)^8+'DCF Model'!J23/(1+H$4)^9+'DCF Model'!K23/(1+H$4)^10+('DCF Model'!K23*(1+$A7)/(H$4-$A7))/(1+H$4)^10-Assumptions!B41)/Assumptions!B39 -> 66.808098
A8: 0.025 | B8: =('DCF Model'!B23/(1+B$4)^1+'DCF Model'!C23/(1+B$4)^2+'DCF Model'!D23/(1+B$4)^3+'DCF Model'!E23/(1+B$4)^4+'DCF Model'!F23/(1+B$4)^5+'DCF Model'!G23/(1+B$4)^6+'DCF Model'!H23/(1+B$4)^7+'DCF Model'!I23/(1+B$4)^8+'DCF Model'!J23/(1+B$4)^9+'DCF Model'!K23/(1+B$4)^10+('DCF Model'!K23*(1+$A8)/(B$4-$A8))/(1+B$4)^10-Assumptions!B41)/Assumptions!B39 -> 144.72274 | C8: =('DCF Model'!B23/(1+C$4)^1+'DCF Model'!C23/(1+C$4)^2+'DCF Model'!D23/(1+C$4)^3+'DCF Model'!E23/(1+C$4)^4+'DCF Model'!F23/(1+C$4)^5+'DCF Model'!G23/(1+C$4)^6+'DCF Model'!H23/(1+C$4)^7+'DCF Model'!I23/(1+C$4)^8+'DCF Model'!J23/(1+C$4)^9+'DCF Model'!K23/(1+C$4)^10+('DCF Model'!K23*(1+$A8)/(C$4-$A8))/(1+C$4)^10-Assumptions!B41)/Assumptions!B39 -> 125.45252 | D8: =('DCF Model'!B23/(1+D$4)^1+'DCF Model'!C23/(1+D$4)^2+'DCF Model'!D23/(1+D$4)^3+'DCF Model'!E23/(1+D$4)^4+'DCF Model'!F23/(1+D$4)^5+'DCF Model'!G23/(1+D$4)^6+'DCF Model'!H23/(1+D$4)^7+'DCF Model'!I23/(1+D$4)^8+'DCF Model'!J23/(1+D$4)^9+'DCF Model'!K23/(1+D$4)^10+('DCF Model'!K23*(1+$A8)/(D$4-$A8))/(1+D$4)^10-Assumptions!B41)/Assumptions!B39 -> 110.04283 | E8: =('DCF Model'!B23/(1+E$4)^1+'DCF Model'!C23/(1+E$4)^2+'DCF Model'!D23/(1+E$4)^3+'DCF Model'!E23/(1+E$4)^4+'DCF Model'!F23/(1+E$4)^5+'DCF Model'!G23/(1+E$4)^6+'DCF Model'!H23/(1+E$4)^7+'DCF Model'!I23/(1+E$4)^8+'DCF Model'!J23/(1+E$4)^9+'DCF Model'!K23/(1+E$4)^10+('DCF Model'!K23*(1+$A8)/(E$4-$A8))/(1+E$4)^10-Assumptions!B41)/Assumptions!B39 -> 97.44057 | F8: =('DCF Model'!B23/(1+F$4)^1+'DCF Model'!C23/(1+F$4)^2+'DCF Model'!D23/(1+F$4)^3+'DCF Model'!E23/(1+F$4)^4+'DCF Model'!F23/(1+F$4)^5+'DCF Model'!G23/(1+F$4)^6+'DCF Model'!H23/(1+F$4)^7+'DCF Model'!I23/(1+F$4)^8+'DCF Model'!J23/(1+F$4)^9+'DCF Model'!K23/(1+F$4)^10+('DCF Model'!K23*(1+$A8)/(F$4-$A8))/(1+F$4)^10-Assumptions!B41)/Assumptions!B39 -> 86.943695 | G8: =('DCF Model'!B23/(1+G$4)^1+'DCF Model'!C23/(1+G$4)^2+'DCF Model'!D23/(1+G$4)^3+'DCF Model'!E23/(1+G$4)^4+'DCF Model'!F23/(1+G$4)^5+'DCF Model'!G23/(1+G$4)^6+'DCF Model'!H23/(1+G$4)^7+'DCF Model'!I23/(1+G$4)^8+'DCF Model'!J23/(1+G$4)^9+'DCF Model'!K23/(1+G$4)^10+('DCF Model'!K23*(1+$A8)/(G$4-$A8))/(1+G$4)^10-Assumptions!B41)/Assumptions!B39 -> 78.066175 | H8: =('DCF Model'!B23/(1+H$4)^1+'DCF Model'!C23/(1+H$4)^2+'DCF Model'!D23/(1+H$4)^3+'DCF Model'!E23/(1+H$4)^4+'DCF Model'!F23/(1+H$4)^5+'DCF Model'!G23/(1+H$4)^6+'DCF Model'!H23/(1+H$4)^7+'DCF Model'!I23/(1+H$4)^8+'DCF Model'!J23/(1+H$4)^9+'DCF Model'!K23/(1+H$4)^10+('DCF Model'!K23*(1+$A8)/(H$4-$A8))/(1+H$4)^10-Assumptions!B41)/Assumptions!B39 -> 70.460853
A9: 0.03 | B9: =('DCF Model'!B23/(1+B$4)^1+'DCF Model'!C23/(1+B$4)^2+'DCF Model'!D23/(1+B$4)^3+'DCF Model'!E23/(1+B$4)^4+'DCF Model'!F23/(1+B$4)^5+'DCF Model'!G23/(1+B$4)^6+'DCF Model'!H23/(1+B$4)^7+'DCF Model'!I23/(1+B$4)^8+'DCF Model'!J23/(1+B$4)^9+'DCF Model'!K23/(1+B$4)^10+('DCF Model'!K23*(1+$A9)/(B$4-$A9))/(1+B$4)^10-Assumptions!B41)/Assumptions!B39 -> 162.31138 | C9: =('DCF Model'!B23/(1+C$4)^1+'DCF Model'!C23/(1+C$4)^2+'DCF Model'!D23/(1+C$4)^3+'DCF Model'!E23/(1+C$4)^4+'DCF Model'!F23/(1+C$4)^5+'DCF Model'!G23/(1+C$4)^6+'DCF Model'!H23/(1+C$4)^7+'DCF Model'!I23/(1+C$4)^8+'DCF Model'!J23/(1+C$4)^9+'DCF Model'!K23/(1+C$4)^10+('DCF Model'!K23*(1+$A9)/(C$4-$A9))/(1+C$4)^10-Assumptions!B41)/Assumptions!B39 -> 138.56788 | D9: =('DCF Model'!B23/(1+D$4)^1+'DCF Model'!C23/(1+D$4)^2+'DCF Model'!D23/(1+D$4)^3+'DCF Model'!E23/(1+D$4)^4+'DCF Model'!F23/(1+D$4)^5+'DCF Model'!G23/(1+D$4)^6+'DCF Model'!H23/(1+D$4)^7+'DCF Model'!I23/(1+D$4)^8+'DCF Model'!J23/(1+D$4)^9+'DCF Model'!K23/(1+D$4)^10+('DCF Model'!K23*(1+$A9)/(D$4-$A9))/(1+D$4)^10-Assumptions!B41)/Assumptions!B39 -> 120.10399 | E9: =('DCF Model'!B23/(1+E$4)^1+'DCF Model'!C23/(1+E$4)^2+'DCF Model'!D23/(1+E$4)^3+'DCF Model'!E23/(1+E$4)^4+'DCF Model'!F23/(1+E$4)^5+'DCF Model'!G23/(1+E$4)^6+'DCF Model'!H23/(1+E$4)^7+'DCF Model'!I23/(1+E$4)^8+'DCF Model'!J23/(1+E$4)^9+'DCF Model'!K23/(1+E$4)^10+('DCF Model'!K23*(1+$A9)/(E$4-$A9))/(1+E$4)^10-Assumptions!B41)/Assumptions!B39 -> 105.33572 | F9: =('DCF Model'!B23/(1+F$4)^1+'DCF Model'!C23/(1+F$4)^2+'DCF Model'!D23/(1+F$4)^3+'DCF Model'!E23/(1+F$4)^4+'DCF Model'!F23/(1+F$4)^5+'DCF Model'!G23/(1+F$4)^6+'DCF Model'!H23/(1+F$4)^7+'DCF Model'!I23/(1+F$4)^8+'DCF Model'!J23/(1+F$4)^9+'DCF Model'!K23/(1+F$4)^10+('DCF Model'!K23*(1+$A9)/(F$4-$A9))/(1+F$4)^10-Assumptions!B41)/Assumptions!B39 -> 93.25509 | G9: =('DCF Model'!B23/(1+G$4)^1+'DCF Model'!C23/(1+G$4)^2+'DCF Model'!D23/(1+G$4)^3+'DCF Model'!E23/(1+G$4)^4+'DCF Model'!F23/(1+G$4)^5+'DCF Model'!G23/(1+G$4)^6+'DCF Model'!H23/(1+G$4)^7+'DCF Model'!I23/(1+G$4)^8+'DCF Model'!J23/(1+G$4)^9+'DCF Model'!K23/(1+G$4)^10+('DCF Model'!K23*(1+$A9)/(G$4-$A9))/(1+G$4)^10-Assumptions!B41)/Assumptions!B39 -> 83.190112 | H9: =('DCF Model'!B23/(1+H$4)^1+'DCF Model'!C23/(1+H$4)^2+'DCF Model'!D23/(1+H$4)^3+'DCF Model'!E23/(1+H$4)^4+'DCF Model'!F23/(1+H$4)^5+'DCF Model'!G23/(1+H$4)^6+'DCF Model'!H23/(1+H$4)^7+'DCF Model'!I23/(1+H$4)^8+'DCF Model'!J23/(1+H$4)^9+'DCF Model'!K23/(1+H$4)^10+('DCF Model'!K23*(1+$A9)/(H$4-$A9))/(1+H$4)^10-Assumptions!B41)/Assumptions!B39 -> 74.67557
A10: 0.035 | B10: =('DCF Model'!B23/(1+B$4)^1+'DCF Model'!C23/(1+B$4)^2+'DCF Model'!D23/(1+B$4)^3+'DCF Model'!E23/(1+B$4)^4+'DCF Model'!F23/(1+B$4)^5+'DCF Model'!G23/(1+B$4)^6+'DCF Model'!H23/(1+B$4)^7+'DCF Model'!I23/(1+B$4)^8+'DCF Model'!J23/(1+B$4)^9+'DCF Model'!K23/(1+B$4)^10+('DCF Model'!K23*(1+$A10)/(B$4-$A10))/(1+B$4)^10-Assumptions!B41)/Assumptions!B39 -> 185.76291 | C10: =('DCF Model'!B23/(1+C$4)^1+'DCF Model'!C23/(1+C$4)^2+'DCF Model'!D23/(1+C$4)^3+'DCF Model'!E23/(1+C$4)^4+'DCF Model'!F23/(1+C$4)^5+'DCF Model'!G23/(1+C$4)^6+'DCF Model'!H23/(1+C$4)^7+'DCF Model'!I23/(1+C$4)^8+'DCF Model'!J23/(1+C$4)^9+'DCF Model'!K23/(1+C$4)^10+('DCF Model'!K23*(1+$A10)/(C$4-$A10))/(1+C$4)^10-Assumptions!B41)/Assumptions!B39 -> 155.4305 | D10: =('DCF Model'!B23/(1+D$4)^1+'DCF Model'!C23/(1+D$4)^2+'DCF Model'!D23/(1+D$4)^3+'DCF Model'!E23/(1+D$4)^4+'DCF Model'!F23/(1+D$4)^5+'DCF Model'!G23/(1+D$4)^6+'DCF Model'!H23/(1+D$4)^7+'DCF Model'!I23/(1+D$4)^8+'DCF Model'!J23/(1+D$4)^9+'DCF Model'!K23/(1+D$4)^10+('DCF Model'!K23*(1+$A10)/(D$4-$A10))/(1+D$4)^10-Assumptions!B41)/Assumptions!B39 -> 132.68045 | E10: =('DCF Model'!B23/(1+E$4)^1+'DCF Model'!C23/(1+E$4)^2+'DCF Model'!D23/(1+E$4)^3+'DCF Model'!E23/(1+E$4)^4+'DCF Model'!F23/(1+E$4)^5+'DCF Model'!G23/(1+E$4)^6+'DCF Model'!H23/(1+E$4)^7+'DCF Model'!I23/(1+E$4)^8+'DCF Model'!J23/(1+E$4)^9+'DCF Model'!K23/(1+E$4)^10+('DCF Model'!K23*(1+$A10)/(E$4-$A10))/(1+E$4)^10-Assumptions!B41)/Assumptions!B39 -> 114.98535 | F10: =('DCF Model'!B23/(1+F$4)^1+'DCF Model'!C23/(1+F$4)^2+'DCF Model'!D23/(1+F$4)^3+'DCF Model'!E23/(1+F$4)^4+'DCF Model'!F23/(1+F$4)^5+'DCF Model'!G23/(1+F$4)^6+'DCF Model'!H23/(1+F$4)^7+'DCF Model'!I23/(1+F$4)^8+'DCF Model'!J23/(1+F$4)^9+'DCF Model'!K23/(1+F$4)^10+('DCF Model'!K23*(1+$A10)/(F$4-$A10))/(1+F$4)^10-Assumptions!B41)/Assumptions!B39 -> 100.82876 | G10: =('DCF Model'!B23/(1+G$4)^1+'DCF Model'!C23/(1+G$4)^2+'DCF Model'!D23/(1+G$4)^3+'DCF Model'!E23/(1+G$4)^4+'DCF Model'!F23/(1+G$4)^5+'DCF Model'!G23/(1+G$4)^6+'DCF Model'!H23/(1+G$4)^7+'DCF Model'!I23/(1+G$4)^8+'DCF Model'!J23/(1+G$4)^9+'DCF Model'!K23/(1+G$4)^10+('DCF Model'!K23*(1+$A10)/(G$4-$A10))/(1+G$4)^10-Assumptions!B41)/Assumptions!B39 -> 89.245675 | H10: =('DCF Model'!B23/(1+H$4)^1+'DCF Model'!C23/(1+H$4)^2+'DCF Model'!D23/(1+H$4)^3+'DCF Model'!E23/(1+H$4)^4+'DCF Model'!F23/(1+H$4)^5+'DCF Model'!G23/(1+H$4)^6+'DCF Model'!H23/(1+H$4)^7+'DCF Model'!I23/(1+H$4)^8+'DCF Model'!J23/(1+H$4)^9+'DCF Model'!K23/(1+H$4)^10+('DCF Model'!K23*(1+$A10)/(H$4-$A10))/(1+H$4)^10-Assumptions!B41)/Assumptions!B39 -> 79.59274
A12: Implied Share Price: Rev Growth (2027) vs Operating Ratio (2027)
A13: Rev Growth → | B13: 0.02 | C13: 0.03 | D13: 0.04 | E13: 0.05 | F13: 0.06
A14: Op. Ratio ↓
A15: 0.62 | B15: ='DCF Model'!B46+(('DCF Model'!B8*(1+B$13)*(1-$A15)-'DCF Model'!B8*(1+Assumptions!F7)*(1-Assumptions!F10))*(1-Assumptions!B20)/(1+Assumptions!B33)^2)/Assumptions!B39 -> 124.3166 | C15: ='DCF Model'!B46+(('DCF Model'!B8*(1+C$13)*(1-$A15)-'DCF Model'!B8*(1+Assumptions!F7)*(1-Assumptions!F10))*(1-Assumptions!B20)/(1+Assumptions!B33)^2)/Assumptions!B39 -> 124.38695 | D15: ='DCF Model'!B46+(('DCF Model'!B8*(1+D$13)*(1-$A15)-'DCF Model'!B8*(1+Assumptions!F7)*(1-Assumptions!F10))*(1-Assumptions!B20)/(1+Assumptions!B33)^2)/Assumptions!B39 -> 124.4573 | E15: ='DCF Model'!B46+(('DCF Model'!B8*(1+E$13)*(1-$A15)-'DCF Model'!B8*(1+Assumptions!F7)*(1-Assumptions!F10))*(1-Assumptions!B20)/(1+Assumptions!B33)^2)/Assumptions!B39 -> 124.52765 | F15: ='DCF Model'!B46+(('DCF Model'!B8*(1+F$13)*(1-$A15)-'DCF Model'!B8*(1+Assumptions!F7)*(1-Assumptions!F10))*(1-Assumptions!B20)/(1+Assumptions!B33)^2)/Assumptions!B39 -> 124.598
A16: 0.61 | B16: ='DCF Model'!B46+(('DCF Model'!B8*(1+B$13)*(1-$A16)-'DCF Model'!B8*(1+Assumptions!F7)*(1-Assumptions!F10))*(1-Assumptions!B20)/(1+Assumptions!B33)^2)/Assumptions!B39 -> 124.50543 | C16: ='DCF Model'!B46+(('DCF Model'!B8*(1+C$13)*(1-$A16)-'DCF Model'!B8*(1+Assumptions!F7)*(1-Assumptions!F10))*(1-Assumptions!B20)/(1+Assumptions!B33)^2)/Assumptions!B39 -> 124.57763 | D16: ='DCF Model'!B46+(('DCF Model'!B8*(1+D$13)*(1-$A16)-'DCF Model'!B8*(1+Assumptions!F7)*(1-Assumptions!F10))*(1-Assumptions!B20)/(1+Assumptions!B33)^2)/Assumptions!B39 -> 124.64983 | E16: ='DCF Model'!B46+(('DCF Model'!B8*(1+E$13)*(1-$A16)-'DCF Model'!B8*(1+Assumptions!F7)*(1-Assumptions!F10))*(1-Assumptions!B20)/(1+Assumptions!B33)^2)/Assumptions!B39 -> 124.72203 | F16: ='DCF Model'!B46+(('DCF Model'!B8*(1+F$13)*(1-$A16)-'DCF Model'!B8*(1+Assumptions!F7)*(1-Assumptions!F10))*(1-Assumptions!B20)/(1+Assumptions!B33)^2)/Assumptions!B39 -> 124.79423
A17: 0.6 | B17: ='DCF Model'!B46+(('DCF Model'!B8*(1+B$13)*(1-$A17)-'DCF Model'!B8*(1+Assumptions!F7)*(1-Assumptions!F10))*(1-Assumptions!B20)/(1+Assumptions!B33)^2)/Assumptions!B39 -> 124.69426 | C17: ='DCF Model'!B46+(('DCF Model'!B8*(1+C$13)*(1-$A17)-'DCF Model'!B8*(1+Assumptions!F7)*(1-Assumptions!F10))*(1-Assumptions!B20)/(1+Assumptions!B33)^2)/Assumptions!B39 -> 124.76831 | D17: ='DCF Model'!B46+(('DCF Model'!B8*(1+D$13)*(1-$A17)-'DCF Model'!B8*(1+Assumptions!F7)*(1-Assumptions!F10))*(1-Assumptions!B20)/(1+Assumptions!B33)^2)/Assumptions!B39 -> 124.84237 | E17: ='DCF Model'!B46+(('DCF Model'!B8*(1+E$13)*(1-$A17)-'DCF Model'!B8*(1+Assumptions!F7)*(1-Assumptions!F10))*(1-Assumptions!B20)/(1+Assumptions!B33)^2)/Assumptions!B39 -> 124.91642 | F17: ='DCF Model'!B46+(('DCF Model'!B8*(1+F$13)*(1-$A17)-'DCF Model'!B8*(1+Assumptions!F7)*(1-Assumptions!F10))*(1-Assumptions!B20)/(1+Assumptions!B33)^2)/Assumptions!B39 -> 124.99047
A18: 0.59 | B18: ='DCF Model'!B46+(('DCF Model'!B8*(1+B$13)*(1-$A18)-'DCF Model'!B8*(1+Assumptions!F7)*(1-Assumptions!F10))*(1-Assumptions!B20)/(1+Assumptions!B33)^2)/Assumptions!B39 -> 124.88309 | C18: ='DCF Model'!B46+(('DCF Model'!B8*(1+C$13)*(1-$A18)-'DCF Model'!B8*(1+Assumptions!F7)*(1-Assumptions!F10))*(1-Assumptions!B20)/(1+Assumptions!B33)^2)/Assumptions!B39 -> 124.959 | D18: ='DCF Model'!B46+(('DCF Model'!B8*(1+D$13)*(1-$A18)-'DCF Model'!B8*(1+Assumptions!F7)*(1-Assumptions!F10))*(1-Assumptions!B20)/(1+Assumptions!B33)^2)/Assumptions!B39 -> 125.0349 | E18: ='DCF Model'!B46+(('DCF Model'!B8*(1+E$13)*(1-$A18)-'DCF Model'!B8*(1+Assumptions!F7)*(1-Assumptions!F10))*(1-Assumptions!B20)/(1+Assumptions!B33)^2)/Assumptions!B39 -> 125.1108 | F18: ='DCF Model'!B46+(('DCF Model'!B8*(1+F$13)*(1-$A18)-'DCF Model'!B8*(1+Assumptions!F7)*(1-Assumptions!F10))*(1-Assumptions!B20)/(1+Assumptions!B33)^2)/Assumptions!B39 -> 125.18671
A19: 0.58 | B19: ='DCF Model'!B46+(('DCF Model'!B8*(1+B$13)*(1-$A19)-'DCF Model'!B8*(1+Assumptions!F7)*(1-Assumptions!F10))*(1-Assumptions!B20)/(1+Assumptions!B33)^2)/Assumptions!B39 -> 125.07193 | C19: ='DCF Model'!B46+(('DCF Model'!B8*(1+C$13)*(1-$A19)-'DCF Model'!B8*(1+Assumptions!F7)*(1-Assumptions!F10))*(1-Assumptions!B20)/(1+Assumptions!B33)^2)/Assumptions!B39 -> 125.14968 | D19: ='DCF Model'!B46+(('DCF Model'!B8*(1+D$13)*(1-$A19)-'DCF Model'!B8*(1+Assumptions!F7)*(1-Assumptions!F10))*(1-Assumptions!B20)/(1+Assumptions!B33)^2)/Assumptions!B39 -> 125.22744 | E19: ='DCF Model'!B46+(('DCF Model'!B8*(1+E$13)*(1-$A19)-'DCF Model'!B8*(1+Assumptions!F7)*(1-Assumptions!F10))*(1-Assumptions!B20)/(1+Assumptions!B33)^2)/Assumptions!B39 -> 125.30519 | F19: ='DCF Model'!B46+(('DCF Model'!B8*(1+F$13)*(1-$A19)-'DCF Model'!B8*(1+Assumptions!F7)*(1-Assumptions!F10))*(1-Assumptions!B20)/(1+Assumptions!B33)^2)/Assumptions!B39 -> 125.38294

Sheet Valuation Summary
A1: CN Rail — Valuation Summary
A2: Multiple Approaches · C$ per share
A4: Methodology | B4: Low | C4: Mid | D4: High | E4: Commentary
A5: DCF (Base Case) | B5: ='DCF Model'!B46*0.9 -> 112.27149 | C5: ='DCF Model'!B46 -> 124.7461 | D5: ='DCF Model'!B46*1.1 -> 137.22071 | E5: Gordon Growth TV; WACC range ±50bps
A6: Forward P/E (Consensus 2026 EPS) | B6: 138.89 | C6: 159.315 | D6: 179.74 | E6: 17x / 19.5x / 22x FY2026E EPS of C$8.17
A7: EV/EBITDA (FY2026E) | B7: =(10.5*('DCF Model'!B13+'DCF Model'!B19)-Assumptions!B41)/Assumptions!B39 -> 118.62506 | C7: =(12*('DCF Model'!B13+'DCF Model'!B19)-Assumptions!B41)/Assumptions!B39 -> 139.37334 | D7: =(13.5*('DCF Model'!B13+'DCF Model'!B19)-Assumptions!B41)/Assumptions!B39 -> 160.12162 | E7: 10.5x / 12.0x / 13.5x FY2026E EBITDA
A8: Dividend Discount (DDM) | B8: =3.5256/((Assumptions!B27+0.005)-0.04) -> 80.585143 | C8: =3.5595/((Assumptions!B27+0)-0.05) -> 123.8087 | D8: =3.5934/((Assumptions!B27+-0.005)-0.06) -> 261.33818 | E8: 4%/5%/6% dividend growth; Ke from CAPM ± 50bps
A9: Morningstar Fair Value (ref.) | B9: 155 | C9: 171 | D9: 171 | E9: ~US$123 ≈ C$171 at 0.72 FX; Source: Morningstar Mar 2026
A11: Current Price (C$) | B11: =Assumptions!B40 -> 141
A12: 52-Week Range (C$) | B12: 127 | C12: 176
A14: Key Assumptions Behind Base Case DCF
A15: • Revenue CAGR of ~3.5% (FY2026-2035), driven by potash ramp, intermodal recovery, and pricing
A16: • Operating ratio improving from 61.2% to 58.5% terminal (industry floor ~high 58s per consensus)
A17: • Capex declining from 21% to 18% of revenue as major projects (Prince Rupert, Edmonton) complete
A18: • WACC of ~7.9% reflecting 0.85 beta, 5.5% ERP, 3.2% risk-free rate
A19: • Terminal growth of 2.5% (long-term nominal GDP; CN is inflation-protected via pricing escalators)
A20: • Tax rate held flat at 25.5% (Canadian statutory); no material tax structure changes assumed
A21: • Net debt of C$16.5B; management targets return to 2.5x leverage by 2027
